Workbook

Sheet 2025
A1: Pick | B1: Intro | C1: Winner | D1: Type | E1: Name | F1: Salary | G1: Term | H1: Picks Transferred | U1: UFA | V1: UFA Rank | W1: RFA | X1: RFA Rank
A2: 1 | B2: GVR | C2: MAC | D2: RFA | E2: Mikko Rantanen | F2: 6.5 | G2: 4 | H2: 2028 1st (MAC) | I2: 2030 1st (MAC) | J2: 2030 2nd (MAC) | K2: 2029 3rd (MAC) | U2: =if($D2=U$1,$F2,"") | V2: =rank(U2,$U$2:$U$173) -> #N/A | W2: =if($D2=W$1,$F2,"") -> 6.5 | X2: =rank(W2,$W$2:$W$173) -> 2
A3: =A2+1 -> 2 | B3: GVR | C3: HSM | D3: UFA | E3: Connor Hellebuyck | F3: 8.4 | G3: 1 | U3: =if($D3=U$1,$F3,"") -> 8.4 | V3: =rank(U3,$U$2:$U$173) -> 2 | W3: =if($D3=W$1,$F3,"") | X3: =rank(W3,$W$2:$W$173) -> #N/A
A4: =A3+1 -> 3 | B4: BOT | C4: BOT | D4: RFA | E4: Timo Meier | F4: 3.2 | G4: 1 | U4: =if($D4=U$1,$F4,"") | V4: =rank(U4,$U$2:$U$173) -> #N/A | W4: =if($D4=W$1,$F4,"") -> 3.2 | X4: =rank(W4,$W$2:$W$173) -> 8
A5: =A4+1 -> 4 | B5: BOT | C5: ZSK | D5: UFA | E5: Nikita Kucherov | F5: 10 | G5: 1 | U5: =if($D5=U$1,$F5,"") -> 10 | V5: =rank(U5,$U$2:$U$173) -> 1 | W5: =if($D5=W$1,$F5,"") | X5: =rank(W5,$W$2:$W$173) -> #N/A
A6: =A5+1 -> 5 | B6: SRL | C6: GVR | D6: RFA | E6: Evan Bouchard | F6: 5.6 | G6: 2 | U6: =if($D6=U$1,$F6,"") | V6: =rank(U6,$U$2:$U$173) -> #N/A | W6: =if($D6=W$1,$F6,"") -> 5.6 | X6: =rank(W6,$W$2:$W$173) -> 4
A7: =A6+1 -> 6 | B7: SRL | C7: LGN | D7: UFA | E7: Juuse Saros | F7: 2.2 | G7: 2 | U7: =if($D7=U$1,$F7,"") -> 2.2 | V7: =rank(U7,$U$2:$U$173) -> 36 | W7: =if($D7=W$1,$F7,"") | X7: =rank(W7,$W$2:$W$173) -> #N/A
A8: =A7+1 -> 7 | B8: ZSK | C8: HSM | D8: RFA | E8: Auston Matthews | F8: 6.6 | G8: 3 | U8: =if($D8=U$1,$F8,"") | V8: =rank(U8,$U$2:$U$173) -> #N/A | W8: =if($D8=W$1,$F8,"") -> 6.6 | X8: =rank(W8,$W$2:$W$173) -> 1
A9: =A8+1 -> 8 | B9: ZSK | C9: BOT | D9: UFA | E9: Artemi Panarin | F9: 7.6 | G9: 1 | U9: =if($D9=U$1,$F9,"") -> 7.6 | V9: =rank(U9,$U$2:$U$173) -> 3 | W9: =if($D9=W$1,$F9,"") | X9: =rank(W9,$W$2:$W$173) -> #N/A
A10: =A9+1 -> 9 | B10: MAC | C10: MAC | D10: RFA | E10: Alex DeBrincat | F10: 3.2 | G10: 1 | U10: =if($D10=U$1,$F10,"") | V10: =rank(U10,$U$2:$U$173) -> #N/A | W10: =if($D10=W$1,$F10,"") -> 3.2 | X10: =rank(W10,$W$2:$W$173) -> 8
A11: =A10+1 -> 10 | B11: MAC | C11: ZSK | D11: UFA | E11: Ryan Nugent-Hopkins | F11: 1.9 | G11: 1 | U11: =if($D11=U$1,$F11,"") -> 1.9 | V11: =rank(U11,$U$2:$U$173) -> 44 | W11: =if($D11=W$1,$F11,"") | X11: =rank(W11,$W$2:$W$173) -> #N/A
A12: =A11+1 -> 11 | B12: SHF | C12: SHF | D12: RFA | E12: Pyotr Kochetkov | F12: 2.4 | G12: 3 | H12: 2028 2nd (SHF) | U12: =if($D12=U$1,$F12,"") | V12: =rank(U12,$U$2:$U$173) -> #N/A | W12: =if($D12=W$1,$F12,"") -> 2.4 | X12: =rank(W12,$W$2:$W$173) -> 13
A13: =A12+1 -> 12 | B13: SHF | C13: MAC | D13: UFA | E13: Andrei Vasilevsky | F13: 7.4 | G13: 1 | U13: =if($D13=U$1,$F13,"") -> 7.4 | V13: =rank(U13,$U$2:$U$173) -> 4 | W13: =if($D13=W$1,$F13,"") | X13: =rank(W13,$W$2:$W$173) -> #N/A
A14: =A13+1 -> 13 | B14: LPT | C14: JHN | D14: RFA | E14: Dylan Larkin | F14: 2.7 | G14: 4 | U14: =if($D14=U$1,$F14,"") | V14: =rank(U14,$U$2:$U$173) -> #N/A | W14: =if($D14=W$1,$F14,"") -> 2.7 | X14: =rank(W14,$W$2:$W$173) -> 11
A15: =A14+1 -> 14 | B15: LPT | C15: JHN | D15: UFA | E15: Sergei Bobrovsky | F15: 6.5 | G15: 1 | U15: =if($D15=U$1,$F15,"") -> 6.5 | V15: =rank(U15,$U$2:$U$173) -> 5 | W15: =if($D15=W$1,$F15,"") | X15: =rank(W15,$W$2:$W$173) -> #N/A
A16: =A15+1 -> 15 | B16: LGN | C16: LPT | D16: RFA | E16: Kyle Connor | F16: 5.8 | G16: 4 | H16: 2027 1st (HSM) | I16: 2026 2nd (LPT) | J16: 2026 3rd (LPT) | K16: 2027 3rd (MAC) | U16: =if($D16=U$1,$F16,"") | V16: =rank(U16,$U$2:$U$173) -> #N/A | W16: =if($D16=W$1,$F16,"") -> 5.8 | X16: =rank(W16,$W$2:$W$173) -> 3
A17: =A16+1 -> 16 | B17: LGN | C17: BOT | D17: UFA | E17: Travis Konecny | F17: 3.4 | G17: 1 | U17: =if($D17=U$1,$F17,"") -> 3.4 | V17: =rank(U17,$U$2:$U$173) -> 19 | W17: =if($D17=W$1,$F17,"") | X17: =rank(W17,$W$2:$W$173) -> #N/A
A18: =A17+1 -> 17 | B18: HSM | C18: HSM | D18: UFA | E18: Aaron Ekblad | F18: 1.6 | G18: 1 | U18: =if($D18=U$1,$F18,"") -> 1.6 | V18: =rank(U18,$U$2:$U$173) -> 52 | W18: =if($D18=W$1,$F18,"") | X18: =rank(W18,$W$2:$W$173) -> #N/A
A19: =A18+1 -> 18 | B19: VPP | C19: HSM | D19: RFA | E19: Jack Hughes | F19: 5.6 | G19: 3 | U19: =if($D19=U$1,$F19,"") | V19: =rank(U19,$U$2:$U$173) -> #N/A | W19: =if($D19=W$1,$F19,"") -> 5.6 | X19: =rank(W19,$W$2:$W$173) -> 4
A20: =A19+1 -> 19 | B20: VPP | C20: LPT | D20: UFA | E20: Sidney Crosby | F20: 5.2 | G20: 1 | U20: =if($D20=U$1,$F20,"") -> 5.2 | V20: =rank(U20,$U$2:$U$173) -> 11 | W20: =if($D20=W$1,$F20,"") | X20: =rank(W20,$W$2:$W$173) -> #N/A
A21: =A20+1 -> 20 | B21: JHN | C21: ZSK | D21: RFA | E21: Seth Jarvis | F21: 3.2 | G21: 6 | H21: 2027 2nd (ZSK) | I21: 2027 3rd (GVR) | U21: =if($D21=U$1,$F21,"") | V21: =rank(U21,$U$2:$U$173) -> #N/A | W21: =if($D21=W$1,$F21,"") -> 3.2 | X21: =rank(W21,$W$2:$W$173) -> 8
A22: =A21+1 -> 21 | B22: JHN | C22: JHN | D22: UFA | E22: Sam Reinhart | F22: 6.4 | G22: 2 | U22: =if($D22=U$1,$F22,"") -> 6.4 | V22: =rank(U22,$U$2:$U$173) -> 6 | W22: =if($D22=W$1,$F22,"") | X22: =rank(W22,$W$2:$W$173) -> #N/A
A23: =A22+1 -> 22 | B23: GVR | C23: LGN | D23: RFA | E23: Kirill Marchenko | F23: 2.7 | G23: 3 | H23: 2026 2nd (HSM) | I23: 2027 3rd (LPT) | U23: =if($D23=U$1,$F23,"") | V23: =rank(U23,$U$2:$U$173) -> #N/A | W23: =if($D23=W$1,$F23,"") -> 2.7 | X23: =rank(W23,$W$2:$W$173) -> 11
A24: =A23+1 -> 23 | B24: GVR | C24: JHN | D24: UFA | E24: Jake Guentzel | F24: 5.9 | G24: 1 | U24: =if($D24=U$1,$F24,"") -> 5.9 | V24: =rank(U24,$U$2:$U$173) -> 8 | W24: =if($D24=W$1,$F24,"") | X24: =rank(W24,$W$2:$W$173) -> #N/A
A25: =A24+1 -> 24 | B25: BOT | C25: HSM | D25: RFA | E25: Clayton Keller | F25: 3.3 | G25: 5 | U25: =if($D25=U$1,$F25,"") | V25: =rank(U25,$U$2:$U$173) -> #N/A | W25: =if($D25=W$1,$F25,"") -> 3.3 | X25: =rank(W25,$W$2:$W$173) -> 7
A26: =A25+1 -> 25 | B26: BOT | C26: LPT | D26: UFA | E26: Mark Scheifele | F26: 5.7 | G26: 1 | U26: =if($D26=U$1,$F26,"") -> 5.7 | V26: =rank(U26,$U$2:$U$173) -> 9 | W26: =if($D26=W$1,$F26,"") | X26: =rank(W26,$W$2:$W$173) -> #N/A
A27: =A26+1 -> 26 | B27: SRL | C27: GVR | D27: RFA | E27: Matt Boldy | F27: 3.4 | G27: 2 | U27: =if($D27=U$1,$F27,"") | V27: =rank(U27,$U$2:$U$173) -> #N/A | W27: =if($D27=W$1,$F27,"") -> 3.4 | X27: =rank(W27,$W$2:$W$173) -> 6
A28: =A27+1 -> 27 | B28: SRL | C28: JHN | D28: UFA | E28: Zach Hyman | F28: 2 | G28: 1 | U28: =if($D28=U$1,$F28,"") -> 2 | V28: =rank(U28,$U$2:$U$173) -> 40 | W28: =if($D28=W$1,$F28,"") | X28: =rank(W28,$W$2:$W$173) -> #N/A
A29: =A28+1 -> 28 | B29: ZSK | C29: BOT | D29: RFA | E29: Drake Batherson | F29: 1.9 | G29: 1 | U29: =if($D29=U$1,$F29,"") | V29: =rank(U29,$U$2:$U$173) -> #N/A | W29: =if($D29=W$1,$F29,"") -> 1.9 | X29: =rank(W29,$W$2:$W$173) -> 15
A30: =A29+1 -> 29 | B30: ZSK | C30: ZSK | D30: UFA | E30: Mathew Barzal | F30: 2.3 | G30: 2 | U30: =if($D30=U$1,$F30,"") -> 2.3 | V30: =rank(U30,$U$2:$U$173) -> 34 | W30: =if($D30=W$1,$F30,"") | X30: =rank(W30,$W$2:$W$173) -> #N/A
A31: =A30+1 -> 30 | B31: MAC | C31: BOT | D31: RFA | E31: Noah Dobson | F31: 2 | G31: 2 | U31: =if($D31=U$1,$F31,"") | V31: =rank(U31,$U$2:$U$173) -> #N/A | W31: =if($D31=W$1,$F31,"") -> 2 | X31: =rank(W31,$W$2:$W$173) -> 14
A32: =A31+1 -> 31 | B32: MAC | C32: LPT | D32: UFA | E32: Sam Bennett | F32: 1.3 | G32: 1 | U32: =if($D32=U$1,$F32,"") -> 1.3 | V32: =rank(U32,$U$2:$U$173) -> 60 | W32: =if($D32=W$1,$F32,"") | X32: =rank(W32,$W$2:$W$173) -> #N/A
A33: =A32+1 -> 32 | B33: SHF | C33: ZSK | D33: RFA | E33: Lukas Dostal | F33: 0.9 | G33: 4 | U33: =if($D33=U$1,$F33,"") | V33: =rank(U33,$U$2:$U$173) -> #N/A | W33: =if($D33=W$1,$F33,"") -> 0.9 | X33: =rank(W33,$W$2:$W$173) -> 17
A34: =A33+1 -> 33 | B34: SHF | C34: SRL | D34: UFA | E34: Darcy Kuemper | F34: 3.7 | G34: 1 | U34: =if($D34=U$1,$F34,"") -> 3.7 | V34: =rank(U34,$U$2:$U$173) -> 18 | W34: =if($D34=W$1,$F34,"") | X34: =rank(W34,$W$2:$W$173) -> #N/A
A35: =A34+1 -> 34 | B35: LPT | C35: JHN | D35: RFA | E35: Troy Terry | F35: 1.6 | G35: 1 | U35: =if($D35=U$1,$F35,"") | V35: =rank(U35,$U$2:$U$173) -> #N/A | W35: =if($D35=W$1,$F35,"") -> 1.6 | X35: =rank(W35,$W$2:$W$173) -> 16
... A140: =A139+1 -> 139 | B140: SRL | C140: SRL | D140: UFA | E140: Tristan Jarry | F140: 0.5 | G140: 1 | U140: =if($D140=U$1,$F140,"") -> 0.5 | V140: =rank(U140,$U$2:$U$173) -> 104 | W140: =if($D140=W$1,$F140,"") | X140: =rank(W140,$W$2:$W$173) -> #N/A

Sheet 2024
A1: Pick | B1: Intro | C1: Winner | D1: Type | E1: Name | F1: Salary | G1: Term | H1: Picks Transferred | U1: UFA | V1: UFA Rank | W1: RFA | X1: RFA Rank
A2: 1 | B2: GVR | C2: ZSK | D2: RFA | E2: Jake Oettinger | F2: 5.6 | G2: 3 | U2: =if($D2=U$1,$F2,"") | V2: =rank(U2,$U$2:$U$173) -> #N/A | W2: =if($D2=W$1,$F2,"") -> 5.6 | X2: =rank(W2,$W$2:$W$173) -> 4
A3: =A2+1 -> 2 | B3: GVR | C3: SHF | D3: UFA | E3: Sergei Bobrovsky | F3: 6.5 | G3: 1 | U3: =if($D3=U$1,$F3,"") -> 6.5 | V3: =rank(U3,$U$2:$U$173) -> 4 | W3: =if($D3=W$1,$F3,"") | X3: =rank(W3,$W$2:$W$173) -> #N/A
A4: =A3+1 -> 3 | B4: MAC | C4: GVR | D4: RFA | E4: Jason Robertson | F4: 5.6 | G4: 3 | U4: =if($D4=U$1,$F4,"") | V4: =rank(U4,$U$2:$U$173) -> #N/A | W4: =if($D4=W$1,$F4,"") -> 5.6 | X4: =rank(W4,$W$2:$W$173) -> 4
A5: =A4+1 -> 4 | B5: MAC | C5: JHN | D5: UFA | E5: Zach Hyman | F5: 4.7 | G5: 1 | U5: =if($D5=U$1,$F5,"") -> 4.7 | V5: =rank(U5,$U$2:$U$173) -> 12 | W5: =if($D5=W$1,$F5,"") | X5: =rank(W5,$W$2:$W$173) -> #N/A
A6: =A5+1 -> 5 | B6: ZSK | C6: JHN | D6: RFA | E6: Igor Shesterkin | F6: 5.6 | G6: 5 | H6: 2026 2nd (SRL) | I6: 2028 1st (JHN) | U6: =if($D6=U$1,$F6,"") | V6: =rank(U6,$U$2:$U$173) -> #N/A | W6: =if($D6=W$1,$F6,"") -> 5.6 | X6: =rank(W6,$W$2:$W$173) -> 4
A7: =A6+1 -> 6 | B7: ZSK | C7: MAC | D7: UFA | E7: Artermi Panarin | F7: 8.2 | G7: 1 | U7: =if($D7=U$1,$F7,"") -> 8.2 | V7: =rank(U7,$U$2:$U$173) -> 2 | W7: =if($D7=W$1,$F7,"") | X7: =rank(W7,$W$2:$W$173) -> #N/A
A8: =A7+1 -> 7 | B8: HSM | C8: HSM | D8: UFA | E8: Trevor Moore | F8: 0.7 | G8: 2 | U8: =if($D8=U$1,$F8,"") -> 0.7 | V8: =rank(U8,$U$2:$U$173) -> 94 | W8: =if($D8=W$1,$F8,"") | X8: =rank(W8,$W$2:$W$173) -> #N/A
A9: =A8+1 -> 8 | B9: SRL | C9: HSM | D9: RFA | E9: Miro Heiskanen | F9: 5.8 | G9: 2 | H9: 2026 1st (MAC) | I9: 2026 2nd (HSM) | J9: 2027 2nd (HSM) | K9: 2029 3rd (HSM) | U9: =if($D9=U$1,$F9,"") | V9: =rank(U9,$U$2:$U$173) -> #N/A | W9: =if($D9=W$1,$F9,"") -> 5.8 | X9: =rank(W9,$W$2:$W$173) -> 3
A10: =A9+1 -> 9 | B10: SRL | C10: JHN | D10: UFA | E10: Jeff Skinner | F10: 3.6 | G10: 1 | U10: =if($D10=U$1,$F10,"") -> 3.6 | V10: =rank(U10,$U$2:$U$173) -> 17 | W10: =if($D10=W$1,$F10,"") | X10: =rank(W10,$W$2:$W$173) -> #N/A
A11: =A10+1 -> 10 | B11: VPP | C11: SHF | D11: RFA | E11: Nico Hischier | F11: 3.2 | G11: 3 | U11: =if($D11=U$1,$F11,"") | V11: =rank(U11,$U$2:$U$173) -> #N/A | W11: =if($D11=W$1,$F11,"") -> 3.2 | X11: =rank(W11,$W$2:$W$173) -> 11
A12: =A11+1 -> 11 | B12: VPP | C12: LPT | D12: UFA | E12: JT Miller | F12: 5.4 | G12: 1 | U12: =if($D12=U$1,$F12,"") -> 5.4 | V12: =rank(U12,$U$2:$U$173) -> 8 | W12: =if($D12=W$1,$F12,"") | X12: =rank(W12,$W$2:$W$173) -> #N/A
A13: =A12+1 -> 12 | B13: LPT | C13: GVR | D13: RFA | E13: Mitch Marner | F13: 6.4 | G13: 3 | U13: =if($D13=U$1,$F13,"") | V13: =rank(U13,$U$2:$U$173) -> #N/A | W13: =if($D13=W$1,$F13,"") -> 6.4 | X13: =rank(W13,$W$2:$W$173) -> 2
A14: =A13+1 -> 13 | B14: LPT | C14: LGN | D14: UFA | E14: Nazim Kadri | F14: 2.5 | G14: 2 | U14: =if($D14=U$1,$F14,"") -> 2.5 | V14: =rank(U14,$U$2:$U$173) -> 34 | W14: =if($D14=W$1,$F14,"") | X14: =rank(W14,$W$2:$W$173) -> #N/A
A15: =A14+1 -> 14 | B15: LGN | C15: GVR | D15: RFA | E15: Connor McDavid | F15: 11.4 | G15: 7 | U15: =if($D15=U$1,$F15,"") | V15: =rank(U15,$U$2:$U$173) -> #N/A | W15: =if($D15=W$1,$F15,"") -> 11.4 | X15: =rank(W15,$W$2:$W$173) -> 1
A16: =A15+1 -> 15 | B16: LGN | C16: JHN | D16: UFA | E16: Steven Stamkos | F16: 5 | G16: 1 | U16: =if($D16=U$1,$F16,"") -> 5 | V16: =rank(U16,$U$2:$U$173) -> 11 | W16: =if($D16=W$1,$F16,"") | X16: =rank(W16,$W$2:$W$173) -> #N/A
A17: =A16+1 -> 16 | B17: BOT | C17: SRL | D17: RFA | E17: Aleksander Barkov | F17: 5.5 | G17: 3 | H17: 2029 1st (SRL) | I17: 2028 2nd (SRL) | U17: =if($D17=U$1,$F17,"") | V17: =rank(U17,$U$2:$U$173) -> #N/A | W17: =if($D17=W$1,$F17,"") -> 5.5 | X17: =rank(W17,$W$2:$W$173) -> 8
A18: =A17+1 -> 17 | B18: BOT | C18: BOT | D18: UFA | E18: Frederik Andersen | F18: 2 | G18: 1 | U18: =if($D18=U$1,$F18,"") -> 2 | V18: =rank(U18,$U$2:$U$173) -> 43 | W18: =if($D18=W$1,$F18,"") | X18: =rank(W18,$W$2:$W$173) -> #N/A
A19: =A18+1 -> 18 | B19: SHF | C19: SHF | D19: RFA | E19: Stuart Skinner | F19: 5.6 | G19: 3 | H19: 2026 2nd (SHF) | I19: 2026 1st (SRL) | U19: =if($D19=U$1,$F19,"") | V19: =rank(U19,$U$2:$U$173) -> #N/A | W19: =if($D19=W$1,$F19,"") -> 5.6 | X19: =rank(W19,$W$2:$W$173) -> 4
A20: =A19+1 -> 19 | B20: SHF | C20: HSM | D20: UFA | E20: Filip Forsberg | F20: 5.7 | G20: 1 | U20: =if($D20=U$1,$F20,"") -> 5.7 | V20: =rank(U20,$U$2:$U$173) -> 5 | W20: =if($D20=W$1,$F20,"") | X20: =rank(W20,$W$2:$W$173) -> #N/A
A21: =A20+1 -> 20 | B21: JHN | C21: VPP | D21: RFA | E21: Mathew Barzal | F21: 4.9 | G21: 1 | U21: =if($D21=U$1,$F21,"") | V21: =rank(U21,$U$2:$U$173) -> #N/A | W21: =if($D21=W$1,$F21,"") -> 4.9 | X21: =rank(W21,$W$2:$W$173) -> 9
A22: =A21+1 -> 21 | B22: JHN | C22: MAC | D22: UFA | E22: Brent Burns | F22: 2.2 | G22: 1 | U22: =if($D22=U$1,$F22,"") -> 2.2 | V22: =rank(U22,$U$2:$U$173) -> 37 | W22: =if($D22=W$1,$F22,"") | X22: =rank(W22,$W$2:$W$173) -> #N/A
A23: =A22+1 -> 22 | B23: GVR | C23: LGN | D23: RFA | E23: Ukko-Pekka Luukkonen | F23: 2.4 | G23: 2 | U23: =if($D23=U$1,$F23,"") | V23: =rank(U23,$U$2:$U$173) -> #N/A | W23: =if($D23=W$1,$F23,"") -> 2.4 | X23: =rank(W23,$W$2:$W$173) -> 12
A24: =A23+1 -> 23 | B24: GVR | C24: LGN | D24: UFA | E24: Gustav Nyquist | F24: 1.8 | G24: 2 | U24: =if($D24=U$1,$F24,"") -> 1.8 | V24: =rank(U24,$U$2:$U$173) -> 48 | W24: =if($D24=W$1,$F24,"") | X24: =rank(W24,$W$2:$W$173) -> #N/A
A25: =A24+1 -> 24 | B25: MAC | C25: LGN | D25: UFA | E25: Brock Boeser | F25: 3.2 | G25: 2 | H25: 2027 2nd (HSM) | I25: 2026 3rd (LGN) | U25: =if($D25=U$1,$F25,"") -> 3.2 | V25: =rank(U25,$U$2:$U$173) -> 22 | W25: =if($D25=W$1,$F25,"") | X25: =rank(W25,$W$2:$W$173) -> #N/A
A26: =A25+1 -> 25 | B26: MAC | C26: GVR | D26: UFA | E26: Alex Ovechkin | F26: 2.6 | G26: 1 | U26: =if($D26=U$1,$F26,"") -> 2.6 | V26: =rank(U26,$U$2:$U$173) -> 32 | W26: =if($D26=W$1,$F26,"") | X26: =rank(W26,$W$2:$W$173) -> #N/A
A27: =A26+1 -> 26 | B27: ZSK | C27: LGN | D27: RFA | E27: Lucas Raymond | F27: 4.5 | G27: 5 | H27: 2025 1st (LPT) | I27: 2027 3rd (HSM) | U27: =if($D27=U$1,$F27,"") | V27: =rank(U27,$U$2:$U$173) -> #N/A | W27: =if($D27=W$1,$F27,"") -> 4.5 | X27: =rank(W27,$W$2:$W$173) -> 10
A28: =A27+1 -> 27 | B28: ZSK | C28: MAC | D28: UFA | E28: Sidney Crosby | F28: 5.3 | G28: 1 | U28: =if($D28=U$1,$F28,"") -> 5.3 | V28: =rank(U28,$U$2:$U$173) -> 10 | W28: =if($D28=W$1,$F28,"") | X28: =rank(W28,$W$2:$W$173) -> #N/A
A29: =A28+1 -> 28 | B29: HSM | C29: LGN | D29: UFA | E29: Travis Sanheim | F29: 0.9 | G29: 1 | U29: =if($D29=U$1,$F29,"") -> 0.9 | V29: =rank(U29,$U$2:$U$173) -> 75 | W29: =if($D29=W$1,$F29,"") | X29: =rank(W29,$W$2:$W$173) -> #N/A
A30: =A29+1 -> 29 | B30: SRL | C30: SRL | D30: RFA | E30: Owen Tippett | F30: 0.9 | G30: 3 | U30: =if($D30=U$1,$F30,"") | V30: =rank(U30,$U$2:$U$173) -> #N/A | W30: =if($D30=W$1,$F30,"") -> 0.9 | X30: =rank(W30,$W$2:$W$173) -> 17
A31: =A30+1 -> 30 | B31: SRL | C31: ZSK | D31: UFA | E31: Zach Werenski | F31: 3 | G31: 1 | U31: =if($D31=U$1,$F31,"") -> 3 | V31: =rank(U31,$U$2:$U$173) -> 27 | W31: =if($D31=W$1,$F31,"") | X31: =rank(W31,$W$2:$W$173) -> #N/A
A32: =A31+1 -> 31 | B32: VPP | C32: VPP | D32: RFA | E32: Casey Mittelstadt | F32: 1.9 | G32: 3 | U32: =if($D32=U$1,$F32,"") | V32: =rank(U32,$U$2:$U$173) -> #N/A | W32: =if($D32=W$1,$F32,"") -> 1.9 | X32: =rank(W32,$W$2:$W$173) -> 15
A33: =A32+1 -> 32 | B33: VPP | C33: JHN | D33: UFA | E33: Sebastian Aho | F33: 5.7 | G33: 1 | U33: =if($D33=U$1,$F33,"") -> 5.7 | V33: =rank(U33,$U$2:$U$173) -> 5 | W33: =if($D33=W$1,$F33,"") | X33: =rank(W33,$W$2:$W$173) -> #N/A
A34: =A33+1 -> 33 | B34: LPT | C34: ZSK | D34: RFA | E34: Gabe Vilardi | F34: 0.9 | G34: 2 | U34: =if($D34=U$1,$F34,"") | V34: =rank(U34,$U$2:$U$173) -> #N/A | W34: =if($D34=W$1,$F34,"") -> 0.9 | X34: =rank(W34,$W$2:$W$173) -> 17
A35: =A34+1 -> 34 | B35: LPT | C35: BOT | D35: UFA | E35: Chris Kreider | F35: 2.5 | G35: 1 | U35: =if($D35=U$1,$F35,"") -> 2.5 | V35: =rank(U35,$U$2:$U$173) -> 34 | W35: =if($D35=W$1,$F35,"") | X35: =rank(W35,$W$2:$W$173) -> #N/A
A36: =A35+1 -> 35 | B36: LGN | C36: LPT | D36: RFA | E36: Josh Norris | F36: 1.2 | G36: 1 | U36: =if($D36=U$1,$F36,"") | V36: =rank(U36,$U$2:$U$173) -> #N/A | W36: =if($D36=W$1,$F36,"") -> 1.2 | X36: =rank(W36,$W$2:$W$173) -> 16
A37: =A36+1 -> 36 | B37: LGN | C37: LPT | D37: UFA | E37: Roman Josi | F37: 5.4 | G37: 2 | U37: =if($D37=U$1,$F37,"") -> 5.4 | V37: =rank(U37,$U$2:$U$173) -> 8 | W37: =if($D37=W$1,$F37,"") | X37: =rank(W37,$W$2:$W$173) -> #N/A
A38: =A37+1 -> 37 | B38: BOT | C38: LPT | D38: RFA | E38: Alex Tuch | F38: 2 | G38: 2 | U38: =if($D38=U$1,$F38,"") | V38: =rank(U38,$U$2:$U$173) -> #N/A | W38: =if($D38=W$1,$F38,"") -> 2 | X38: =rank(W38,$W$2:$W$173) -> 14
A39: =A38+1 -> 38 | B39: BOT | C39: JHN | D39: UFA | E39: Cam Talbot | F39: 0.7 | G39: 1 | U39: =if($D39=U$1,$F39,"") -> 0.7 | V39: =rank(U39,$U$2:$U$173) -> 94 | W39: =if($D39=W$1,$F39,"") | X39: =rank(W39,$W$2:$W$173) -> #N/A
A40: =A39+1 -> 39 | B40: SHF | C40: SRL | D40: RFA | E40: Martin Necas | F40: 2.4 | G40: 4 | H40: 2029 2nd (SRL) | U40: =if($D40=U$1,$F40,"") | V40: =rank(U40,$U$2:$U$173) -> #N/A | W40: =if($D40=W$1,$F40,"") -> 2.4 | X40: =rank(W40,$W$2:$W$173) -> 12
...

Sheet 2023
A1: Pick | B1: Intro | C1: Winner | D1: Type | E1: Name | F1: Salary | G1: Term | H1: Picks Transferred | U1: UFA | V1: UFA Rank | W1: RFA | X1: RFA Rank
A2: 1 | B2: Drew | C2: Lloyd | D2: RFA | E2: Tage Thompson | F2: 6 | G2: 4 | H2: 2024 1st (SRL) | I2: 2024 3rd | J2: 2025 2nd | K2: 2025 3rd | U2: =if($D2=U$1,$F2,"") | V2: =rank(U2,$U$2:$U$173) -> #N/A | W2: =if($D2=W$1,$F2,"") -> 6 | X2: =rank(W2,$W$2:$W$173) -> 5
A3: =A2+1 -> 2 | B3: Drew | C3: Drew | D3: UFA | E3: Artemi Panarin | F3: 7.3 | G3: 1 | U3: =if($D3=U$1,$F3,"") -> 7.3 | V3: =rank(U3,$U$2:$U$173) -> 2 | W3: =if($D3=W$1,$F3,"") | X3: =rank(W3,$W$2:$W$173) -> #N/A
A4: =A3+1 -> 3 | B4: Tevie | C4: Mike | D4: RFA | E4: Leon Draisaitl | F4: 11.4 | G4: 6 | H4: 2024 1st (BOT), 2025 1st (LPT), 2026 1st (LPT), 2027 1st (LPT) | U4: =if($D4=U$1,$F4,"") | V4: =rank(U4,$U$2:$U$173) -> #N/A | W4: =if($D4=W$1,$F4,"") -> 11.4 | X4: =rank(W4,$W$2:$W$173) -> 1
A5: =A4+1 -> 4 | B5: Tevie | C5: Zale | D5: UFA | E5: Ryan Nugent-Hopkins | F5: 4.5 | G5: 2 | U5: =if($D5=U$1,$F5,"") -> 4.5 | V5: =rank(U5,$U$2:$U$173) -> 11 | W5: =if($D5=W$1,$F5,"") | X5: =rank(W5,$W$2:$W$173) -> #N/A
A6: =A5+1 -> 5 | B6: Kyle | C6: Masliyah | D6: RFA | E6: Shea Theodore | F6: 3.2 | G6: 1 | U6: =if($D6=U$1,$F6,"") | V6: =rank(U6,$U$2:$U$173) -> #N/A | W6: =if($D6=W$1,$F6,"") -> 3.2 | X6: =rank(W6,$W$2:$W$173) -> 12
A7: =A6+1 -> 6 | B7: Kyle | C7: Staav | D7: UFA | E7: Nikita Kucherov | F7: 8.5 | G7: 2 | U7: =if($D7=U$1,$F7,"") -> 8.5 | V7: =rank(U7,$U$2:$U$173) -> 1 | W7: =if($D7=W$1,$F7,"") | X7: =rank(W7,$W$2:$W$173) -> #N/A
A8: =A7+1 -> 7 | B8: Shafran | C8: Tevie | D8: RFA | E8: Nathan MacKinnon | F8: 8.5 | G8: 5 | U8: =if($D8=U$1,$F8,"") | V8: =rank(U8,$U$2:$U$173) -> #N/A | W8: =if($D8=W$1,$F8,"") -> 8.5 | X8: =rank(W8,$W$2:$W$173) -> 2
A9: =A8+1 -> 8 | B9: Shafran | C9: Shafran | D9: UFA | E9: Vitek Vanecek | F9: 5.5 | G9: 1 | U9: =if($D9=U$1,$F9,"") -> 5.5 | V9: =rank(U9,$U$2:$U$173) -> 9 | W9: =if($D9=W$1,$F9,"") | X9: =rank(W9,$W$2:$W$173) -> #N/A
A10: =A9+1 -> 9 | B10: Zale | C10: Kyle | D10: RFA | E10: Ilya Samsonov | F10: 3.2 | G10: 2 | U10: =if($D10=U$1,$F10,"") | V10: =rank(U10,$U$2:$U$173) -> #N/A | W10: =if($D10=W$1,$F10,"") -> 3.2 | X10: =rank(W10,$W$2:$W$173) -> 12
A11: =A10+1 -> 10 | B11: Zale | C11: Tevie | D11: UFA | E11: Sidney Crosby | F11: 6.2 | G11: 1 | U11: =if($D11=U$1,$F11,"") -> 6.2 | V11: =rank(U11,$U$2:$U$173) -> 7 | W11: =if($D11=W$1,$F11,"") | X11: =rank(W11,$W$2:$W$173) -> #N/A
A12: =A11+1 -> 11 | B12: Staav | C12: Staav | D12: RFA | E12: Thatcher Demko | F12: 3 | G12: 3 | U12: =if($D12=U$1,$F12,"") | V12: =rank(U12,$U$2:$U$173) -> #N/A | W12: =if($D12=W$1,$F12,"") -> 3 | X12: =rank(W12,$W$2:$W$173) -> 16
A13: =A12+1 -> 12 | B13: Staav | C13: Craig | D13: UFA | E13: Erik Karlsson | F13: 6.4 | G13: 1 | U13: =if($D13=U$1,$F13,"") -> 6.4 | V13: =rank(U13,$U$2:$U$173) -> 6 | W13: =if($D13=W$1,$F13,"") | X13: =rank(W13,$W$2:$W$173) -> #N/A
A14: =A13+1 -> 13 | B14: Searle | C14: Searle | D14: RFA | E14: Brayden Point | F14: 6.8 | G14: 3 | U14: =if($D14=U$1,$F14,"") | V14: =rank(U14,$U$2:$U$173) -> #N/A | W14: =if($D14=W$1,$F14,"") -> 6.8 | X14: =rank(W14,$W$2:$W$173) -> 3
A15: =A14+1 -> 14 | B15: Searle | C15: Kyle | D15: UFA | E15: Johnny Gaudreau | F15: 4.5 | G15: 1 | U15: =if($D15=U$1,$F15,"") -> 4.5 | V15: =rank(U15,$U$2:$U$173) -> 11 | W15: =if($D15=W$1,$F15,"") | X15: =rank(W15,$W$2:$W$173) -> #N/A
A16: =A15+1 -> 15 | B16: Mike | C16: Shafran | D16: RFA | E16: David Pastrnak | F16: 6.7 | G16: 4 | U16: =if($D16=U$1,$F16,"") | V16: =rank(U16,$U$2:$U$173) -> #N/A | W16: =if($D16=W$1,$F16,"") -> 6.7 | X16: =rank(W16,$W$2:$W$173) -> 4
... A20: =A19+1 -> 19 | B20: Lloyd | C20: Lloyd | D20: UFA | E20: Ilya Sorokin | F20: 6.5 | G20: 1 | U20: =if($D20=U$1,$F20,"") -> 6.5 | V20: =rank(U20,$U$2:$U$173) -> 4 | W20: =if($D20=W$1,$F20,"") | X20: =rank(W20,$W$2:$W$173) -> #N/A
A21: =A20+1 -> 20 | B21: Drew | C21: Kyle | D21: RFA | E21: Josh Morrissey | F21: 4.8 | G21: 2 | H21: 2024 1st (SRL), 2024 3rd (BOT) | U21: =if($D21=U$1,$F21,"") | V21: =rank(U21,$U$2:$U$173) -> #N/A | W21: =if($D21=W$1,$F21,"") -> 4.8 | X21: =rank(W21,$W$2:$W$173) -> 9
A22: =A21+1 -> 21 | B22: Drew | C22: Shafran | D22: UFA | E22: Dougie Hamilton | F22: 4.2 | G22: 2 | U22: =if($D22=U$1,$F22,"") -> 4.2 | V22: =rank(U22,$U$2:$U$173) -> 16 | W22: =if($D22=W$1,$F22,"") | X22: =rank(W22,$W$2:$W$173) -> #N/A
A23: =A22+1 -> 22 | B23: Tevie | C23: Tevie | D23: RFA | E23: Morgan Rielly | F23: 3.2 | G23: 3 | U23: =if($D23=U$1,$F23,"") | V23: =rank(U23,$U$2:$U$173) -> #N/A | W23: =if($D23=W$1,$F23,"") -> 3.2 | X23: =rank(W23,$W$2:$W$173) -> 12
A24: =A23+1 -> 23 | B24: Tevie | C24: Staav | D24: UFA | E24: Jamie Benn | F24: 1.8 | G24: 1 | U24: =if($D24=U$1,$F24,"") -> 1.8 | V24: =rank(U24,$U$2:$U$173) -> 51 | W24: =if($D24=W$1,$F24,"") | X24: =rank(W24,$W$2:$W$173) -> #N/A
A25: =A24+1 -> 24 | B25: Kyle | C25: Searle | D25: RFA | E25: William Nylander | F25: 5.2 | G25: 3 | H25: 2024 1st (MAC), 2025 2nd (SRL) | U25: =if($D25=U$1,$F25,"") | V25: =rank(U25,$U$2:$U$173) -> #N/A | W25: =if($D25=W$1,$F25,"") -> 5.2 | X25: =rank(W25,$W$2:$W$173) -> 8
A26: =A25+1 -> 25 | B26: Kyle | C26: Kyle | D26: UFA | E26: Seth Jones | F26: 1.9 | G26: 1 | U26: =if($D26=U$1,$F26,"") -> 1.9 | V26: =rank(U26,$U$2:$U$173) -> 47 | W26: =if($D26=W$1,$F26,"") | X26: =rank(W26,$W$2:$W$173) -> #N/A
A27: =A26+1 -> 26 | B27: Shafran | C27: Mike | D27: RFA | E27: Rasmus Dahlin | F27: 5.6 | G27: 7 | H27: 2024 1st (MAC), 2025 2nd (SRL) | U27: =if($D27=U$1,$F27,"") | V27: =rank(U27,$U$2:$U$173) -> #N/A | W27: =if($D27=W$1,$F27,"") -> 5.6 | X27: =rank(W27,$W$2:$W$173) -> 6
A28: =A27+1 -> 27 | B28: Shafran | C28: Masliyah | D28: UFA | E28: Connor Hellebuyck | F28: 7.1 | G28: 2 | U28: =if($D28=U$1,$F28,"") -> 7.1 | V28: =rank(U28,$U$2:$U$173) -> 3 | W28: =if($D28=W$1,$F28,"") | X28: =rank(W28,$W$2:$W$173) -> #N/A
A29: =A28+1 -> 28 | B29: Zale | C29: Craig | D29: RFA | E29: Jordan Kyrou | F29: 4 | G29: 5 | U29: =if($D29=U$1,$F29,"") | V29: =rank(U29,$U$2:$U$173) -> #N/A | W29: =if($D29=W$1,$F29,"") -> 4 | X29: =rank(W29,$W$2:$W$173) -> 10
A30: =A29+1 -> 29 | B30: Zale | C30: Craig | D30: UFA | E30: Steven Stamkos | F30: 4.9 | G30: 1 | U30: =if($D30=U$1,$F30,"") -> 4.9 | V30: =rank(U30,$U$2:$U$173) -> 10 | W30: =if($D30=W$1,$F30,"") | X30: =rank(W30,$W$2:$W$173) -> #N/A
A31: =A30+1 -> 30 | B31: Staav | C31: Zale | D31: RFA | E31: Pavel Buchnevich | F31: 2.4 | G31: 4 | U31: =if($D31=U$1,$F31,"") | V31: =rank(U31,$U$2:$U$173) -> #N/A | W31: =if($D31=W$1,$F31,"") -> 2.4 | X31: =rank(W31,$W$2:$W$173) -> 21
A32: =A31+1 -> 31 | B32: Staav | C32: Staav | D32: UFA | E32: Linus Ullmark | F32: 6.5 | G32: 1 | U32: =if($D32=U$1,$F32,"") -> 6.5 | V32: =rank(U32,$U$2:$U$173) -> 4 | W32: =if($D32=W$1,$F32,"") | X32: =rank(W32,$W$2:$W$173) -> #N/A
A33: =A32+1 -> 32 | B33: Searle | C33: Tevie | D33: RFA | E33: Mikhail Sergachev | F33: 3 | G33: 3 | U33: =if($D33=U$1,$F33,"") | V33: =rank(U33,$U$2:$U$173) -> #N/A | W33: =if($D33=W$1,$F33,"") -> 3 | X33: =rank(W33,$W$2:$W$173) -> 16
A34: =A33+1 -> 33 | B34: Searle | C34: Craig | D34: UFA | E34: Evgeni Malkin | F34: 3.5 | G34: 1 | U34: =if($D34=U$1,$F34,"") -> 3.5 | V34: =rank(U34,$U$2:$U$173) -> 21 | W34: =if($D34=W$1,$F34,"") | X34: =rank(W34,$W$2:$W$173) -> #N/A
A35: =A34+1 -> 34 | B35: Mike | C35: Zale | D35: RFA | E35: Nick Suzuki | F35: 3 | G35: 4 | U35: =if($D35=U$1,$F35,"") | V35: =rank(U35,$U$2:$U$173) -> #N/A | W35: =if($D35=W$1,$F35,"") -> 3 | X35: =rank(W35,$W$2:$W$173) -> 16
A36: =A35+1 -> 35 | B36: Mike | C36: Drew | D36: UFA | E36: Mika Zibanejad | F36: 6 | G36: 1 | U36: =if($D36=U$1,$F36,"") -> 6 | V36: =rank(U36,$U$2:$U$173) -> 8 | W36: =if($D36=W$1,$F36,"") | X36: =rank(W36,$W$2:$W$173) -> #N/A
A37: =A36+1 -> 36 | B37: Masliyah | C37: Zale | D37: UFA | E37: Joel Eriksson Ek | F37: 1.6 | G37: 1 | U37: =if($D37=U$1,$F37,"") -> 1.6 | V37: =rank(U37,$U$2:$U$173) -> 55 | W37: =if($D37=W$1,$F37,"") | X37: =rank(W37,$W$2:$W$173) -> #N/A
A38: =A37+1 -> 37 | B38: Craig | C38: Drew | D38: RFA | E38: Sebastian Aho | F38: 5.6 | G38: 1 | U38: =if($D38=U$1,$F38,"") | V38: =rank(U38,$U$2:$U$173) -> #N/A | W38: =if($D38=W$1,$F38,"") -> 5.6 | X38: =rank(W38,$W$2:$W$173) -> 6
A39: =A38+1 -> 38 | B39: Craig | C39: Kyle | D39: UFA | E39: Jeff Skinner | F39: 2.3 | G39: 1 | U39: =if($D39=U$1,$F39,"") -> 2.3 | V39: =rank(U39,$U$2:$U$173) -> 37 | W39: =if($D39=W$1,$F39,"") | X39: =rank(W39,$W$2:$W$173) -> #N/A
... A45: =A44+1 -> 44 | B45: Tevie | C45: Lloyd | D45: UFA | E45: Darnell Nurse | F45: 1.7 | G45: 1 | U45: =if($D45=U$1,$F45,"") -> 1.7 | V45: =rank(U45,$U$2:$U$173) -> 53 | W45: =if($D45=W$1,$F45,"") | X45: =rank(W45,$W$2:$W$173) -> #N/A
A46: =A45+1 -> 45 | B46: Kyle | C46: Kyle | D46: RFA | E46: Aaron Ekblad | F46: 2.2 | G46: 2 | H46: 2024 2nd (MAC) | U46: =if($D46=U$1,$F46,"") | V46: =rank(U46,$U$2:$U$173) -> #N/A | W46: =if($D46=W$1,$F46,"") -> 2.2 | X46: =rank(W46,$W$2:$W$173) -> 22
A47: =A46+1 -> 46 | B47: Kyle | C47: Tevie | D47: UFA | E47: Anze Kopitar | F47: 2.6 | G47: 1 | U47: =if($D47=U$1,$F47,"") -> 2.6 | V47: =rank(U47,$U$2:$U$173) -> 31 | W47: =if($D47=W$1,$F47,"") | X47: =rank(W47,$W$2:$W$173) -> #N/A
A48: =A47+1 -> 47 | B48: Shafran | C48: Kyle | D48: RFA | E48: Drake Batherson | F48: 1.7 | G48: 2 | U48: =if($D48=U$1,$F48,"") | V48: =rank(U48,$U$2:$U$173) -> #N/A | W48: =if($D48=W$1,$F48,"") -> 1.7 | X48: =rank(W48,$W$2:$W$173) -> 24
...

Sheet 2022
A1: Pick | B1: Intro | C1: Winner | D1: Type | E1: Name | F1: Salary | G1: Term | H1: Picks Transferred | U1: UFA | V1: UFA Rank | W1: RFA | X1: RFA Rank
A2: 1 | B2: Drew | C2: Staav | D2: RFA | E2: Cale Makar | F2: 8 | G2: 4 | U2: =if($D2=U$1,$F2,"") | V2: =rank(U2,$U$2:$U$173) -> #N/A | W2: =if($D2=W$1,$F2,"") -> 8 | X2: =rank(W2,$W$2:$W$173) -> 2
A3: =A2+1 -> 2 | B3: Drew | C3: Craig | D3: UFA | E3: Jakob Markstrom | F3: 7.9 | G3: 1 | U3: =if($D3=U$1,$F3,"") -> 7.9 | V3: =rank(U3,$U$2:$U$173) -> 2 | W3: =if($D3=W$1,$F3,"") | X3: =rank(W3,$W$2:$W$173) -> #N/A
A4: =A3+1 -> 3 | B4: Staav | C4: Tevie | D4: RFA | E4: Jonathan Huberdeau | F4: 6 | G4: 4 | U4: =if($D4=U$1,$F4,"") | V4: =rank(U4,$U$2:$U$173) -> #N/A | W4: =if($D4=W$1,$F4,"") -> 6 | X4: =rank(W4,$W$2:$W$173) -> 4
A5: =A4+1 -> 4 | B5: Staav | C5: Kyle | D5: UFA | E5: Roman Josi | F5: 5.4 | G5: 1 | U5: =if($D5=U$1,$F5,"") -> 5.4 | V5: =rank(U5,$U$2:$U$173) -> 14 | W5: =if($D5=W$1,$F5,"") | X5: =rank(W5,$W$2:$W$173) -> #N/A
A6: =A5+1 -> 5 | B6: Tevie | C6: Craig | D6: RFA | E6: Adam Fox | F6: 5 | G6: 6 | U6: =if($D6=U$1,$F6,"") | V6: =rank(U6,$U$2:$U$173) -> #N/A | W6: =if($D6=W$1,$F6,"") -> 5 | X6: =rank(W6,$W$2:$W$173) -> 6
A7: =A6+1 -> 6 | B7: Tevie | C7: Tevie | D7: UFA | E7: Jack Campbell | F7: 6 | G7: 1 | U7: =if($D7=U$1,$F7,"") -> 6 | V7: =rank(U7,$U$2:$U$173) -> 7 | W7: =if($D7=W$1,$F7,"") | X7: =rank(W7,$W$2:$W$173) -> #N/A
A8: =A7+1 -> 7 | B8: Kyle | C8: Zale | D8: RFA | E8: Robert Thomas | F8: 3.3 | G8: 6 | H8: 2023 1st (Zale) | U8: =if($D8=U$1,$F8,"") | V8: =rank(U8,$U$2:$U$173) -> #N/A | W8: =if($D8=W$1,$F8,"") -> 3.3 | X8: =rank(W8,$W$2:$W$173) -> 13
A9: =A8+1 -> 8 | B9: Kyle | C9: Tevie | D9: UFA | E9: Cam Talbot | F9: 2.2 | G9: 1 | U9: =if($D9=U$1,$F9,"") -> 2.2 | V9: =rank(U9,$U$2:$U$173) -> 38 | W9: =if($D9=W$1,$F9,"") | X9: =rank(W9,$W$2:$W$173) -> #N/A
A10: =A9+1 -> 9 | B10: Craig | C10: Mike | D10: RFA | E10: Quinn Hughes | F10: 5.2 | G10: 5 | H10: 2023 2nd (Shafran) | I10: 2024 1st (Lipton) | U10: =if($D10=U$1,$F10,"") | V10: =rank(U10,$U$2:$U$173) -> #N/A | W10: =if($D10=W$1,$F10,"") -> 5.2 | X10: =rank(W10,$W$2:$W$173) -> 5
A11: =A10+1 -> 10 | B11: Craig | C11: Searle | D11: UFA | E11: Victor Hedman | F11: 6.1 | G11: 2 | U11: =if($D11=U$1,$F11,"") -> 6.1 | V11: =rank(U11,$U$2:$U$173) -> 5 | W11: =if($D11=W$1,$F11,"") | X11: =rank(W11,$W$2:$W$173) -> #N/A
A12: =A11+1 -> 11 | B12: Shafran | C12: Mike | D12: RFA | E12: Alex DeBrincat | F12: 3.2 | G12: 3 | U12: =if($D12=U$1,$F12,"") | V12: =rank(U12,$U$2:$U$173) -> #N/A | W12: =if($D12=W$1,$F12,"") -> 3.2 | X12: =rank(W12,$W$2:$W$173) -> 14
A13: =A12+1 -> 12 | B13: Shafran | C13: Masliyah | D13: UFA | E13: Sergei Bobrovsky | F13: 5.4 | G13: 1 | U13: =if($D13=U$1,$F13,"") -> 5.4 | V13: =rank(U13,$U$2:$U$173) -> 14 | W13: =if($D13=W$1,$F13,"") | X13: =rank(W13,$W$2:$W$173) -> #N/A
A14: =A13+1 -> 13 | B14: Mike | C14: Searle | D14: RFA | E14: Kirill Kaprizov | F14: 6.9 | G14: 4 | H14: 2024 2nd (Staav) | I14: 2024 3rd (Staav) | J14: 2025 1st (Searle) | K14: 2026 1st (Searle) | U14: =if($D14=U$1,$F14,"") | V14: =rank(U14,$U$2:$U$173) -> #N/A | W14: =if($D14=W$1,$F14,"") -> 6.9 | X14: =rank(W14,$W$2:$W$173) -> 3
A15: =A14+1 -> 14 | B15: Mike | C15: Shafran | D15: UFA | E15: Artemi Panarin | F15: 8.8 | G15: 1 | U15: =if($D15=U$1,$F15,"") -> 8.8 | V15: =rank(U15,$U$2:$U$173) -> 1 | W15: =if($D15=W$1,$F15,"") | X15: =rank(W15,$W$2:$W$173) -> #N/A
A16: =A15+1 -> 15 | B16: Searle | C16: Searle | D16: RFA | E16: Nikita Kucherov | F16: 9.2 | G16: 1 | U16: =if($D16=U$1,$F16,"") | V16: =rank(U16,$U$2:$U$173) -> #N/A | W16: =if($D16=W$1,$F16,"") -> 9.2 | X16: =rank(W16,$W$2:$W$173) -> 1
A17: =A16+1 -> 16 | B17: Searle | C17: Tevie | D17: UFA | E17: Mark Scheifele | F17: 4.7 | G17: 1 | U17: =if($D17=U$1,$F17,"") -> 4.7 | V17: =rank(U17,$U$2:$U$173) -> 18 | W17: =if($D17=W$1,$F17,"") | X17: =rank(W17,$W$2:$W$173) -> #N/A
A18: =A17+1 -> 17 | B18: Masliyah | C18: Lloyd | D18: UFA | E18: Rasmus Andersson | F18: 1.8 | G18: 1 | U18: =if($D18=U$1,$F18,"") -> 1.8 | V18: =rank(U18,$U$2:$U$173) -> 53 | W18: =if($D18=W$1,$F18,"") | X18: =rank(W18,$W$2:$W$173) -> #N/A
A19: =A18+1 -> 18 | B19: Zale | C19: Lloyd | D19: RFA | E19: Matthew Tkachuk | F19: 5 | G19: 4 | U19: =if($D19=U$1,$F19,"") | V19: =rank(U19,$U$2:$U$173) -> #N/A | W19: =if($D19=W$1,$F19,"") -> 5 | X19: =rank(W19,$W$2:$W$173) -> 6
A20: =A19+1 -> 19 | B20: Zale | C20: Staav | D20: UFA | E20: Alex Ovechkin | F20: 6.1 | G20: 1 | U20: =if($D20=U$1,$F20,"") -> 6.1 | V20: =rank(U20,$U$2:$U$173) -> 5 | W20: =if($D20=W$1,$F20,"") | X20: =rank(W20,$W$2:$W$173) -> #N/A
A21: =A20+1 -> 20 | B21: Lloyd | C21: Masliyah | D21: RFA | E21: Kyle Connor | F21: 4.5 | G21: 3 | U21: =if($D21=U$1,$F21,"") | V21: =rank(U21,$U$2:$U$173) -> #N/A | W21: =if($D21=W$1,$F21,"") -> 4.5 | X21: =rank(W21,$W$2:$W$173) -> 8
A22: =A21+1 -> 21 | B22: Lloyd | C22: Staav | D22: UFA | E22: Mike Zibanejad | F22: 5.5 | G22: 1 | U22: =if($D22=U$1,$F22,"") -> 5.5 | V22: =rank(U22,$U$2:$U$173) -> 13 | W22: =if($D22=W$1,$F22,"") | X22: =rank(W22,$W$2:$W$173) -> #N/A
A23: =A22+1 -> 22 | B23: Drew | C23: Shafran | D23: RFA | E23: Andrei Svechnikov | F23: 3.8 | G23: 8 | U23: =if($D23=U$1,$F23,"") | V23: =rank(U23,$U$2:$U$173) -> #N/A | W23: =if($D23=W$1,$F23,"") -> 3.8 | X23: =rank(W23,$W$2:$W$173) -> 11
A24: =A23+1 -> 23 | B24: Drew | C24: Kyle | D24: UFA | E24: Chris Kreider | F24: 3.1 | G24: 1 | U24: =if($D24=U$1,$F24,"") -> 3.1 | V24: =rank(U24,$U$2:$U$173) -> 29 | W24: =if($D24=W$1,$F24,"") | X24: =rank(W24,$W$2:$W$173) -> #N/A
A25: =A24+1 -> 24 | B25: Staav | C25: Tevie | D25: RFA | E25: Clayton Keller | F25: 2 | G25: 3 | U25: =if($D25=U$1,$F25,"") | V25: =rank(U25,$U$2:$U$173) -> #N/A | W25: =if($D25=W$1,$F25,"") -> 2 | X25: =rank(W25,$W$2:$W$173) -> 21
A26: =A25+1 -> 25 | B26: Staav | C26: Drew | D26: UFA | E26: Patrick Kane | F26: 5.6 | G26: 1 | U26: =if($D26=U$1,$F26,"") -> 5.6 | V26: =rank(U26,$U$2:$U$173) -> 12 | W26: =if($D26=W$1,$F26,"") | X26: =rank(W26,$W$2:$W$173) -> #N/A
A27: =A26+1 -> 26 | B27: Tevie | C27: Lloyd | D27: RFA | E27: Sam Reinhart | F27: 3.6 | G27: 3 | H27: 2024 1st (Lloyd) | U27: =if($D27=U$1,$F27,"") | V27: =rank(U27,$U$2:$U$173) -> #N/A | W27: =if($D27=W$1,$F27,"") -> 3.6 | X27: =rank(W27,$W$2:$W$173) -> 12
A28: =A27+1 -> 27 | B28: Tevie | C28: Mike | D28: UFA | E28: Alexandar Georgiev | F28: 4.7 | G28: 3 | U28: =if($D28=U$1,$F28,"") -> 4.7 | V28: =rank(U28,$U$2:$U$173) -> 18 | W28: =if($D28=W$1,$F28,"") | X28: =rank(W28,$W$2:$W$173) -> #N/A
A29: =A28+1 -> 28 | B29: Kyle | C29: Kyle | D29: RFA | E29: Nicolas Roy | F29: 0.5 | G29: 1 | U29: =if($D29=U$1,$F29,"") | V29: =rank(U29,$U$2:$U$173) -> #N/A | W29: =if($D29=W$1,$F29,"") -> 0.5 | X29: =rank(W29,$W$2:$W$173) -> 31
A30: =A29+1 -> 29 | B30: Kyle | C30: Kyle | D30: UFA | E30: Drew Doughty | F30: 1.9 | G30: 1 | U30: =if($D30=U$1,$F30,"") -> 1.9 | V30: =rank(U30,$U$2:$U$173) -> 48 | W30: =if($D30=W$1,$F30,"") | X30: =rank(W30,$W$2:$W$173) -> #N/A
A31: =A30+1 -> 30 | B31: Craig | C31: Mike | D31: RFA | E31: Timo Meier | F31: 3.2 | G31: 3 | U31: =if($D31=U$1,$F31,"") | V31: =rank(U31,$U$2:$U$173) -> #N/A | W31: =if($D31=W$1,$F31,"") -> 3.2 | X31: =rank(W31,$W$2:$W$173) -> 14
A32: =A31+1 -> 31 | B32: Craig | C32: Craig | D32: UFA | E32: Nazem Kadri | F32: 3.6 | G32: 2 | U32: =if($D32=U$1,$F32,"") -> 3.6 | V32: =rank(U32,$U$2:$U$173) -> 25 | W32: =if($D32=W$1,$F32,"") | X32: =rank(W32,$W$2:$W$173) -> #N/A
A33: =A32+1 -> 32 | B33: Shafran | C33: Drew | D33: RFA | E33: Ilya Samsonov | F33: 2.4 | G33: 1 | H33: 2023 2nd (Drew) | U33: =if($D33=U$1,$F33,"") | V33: =rank(U33,$U$2:$U$173) -> #N/A | W33: =if($D33=W$1,$F33,"") -> 2.4 | X33: =rank(W33,$W$2:$W$173) -> 20
A34: =A33+1 -> 33 | B34: Shafran | C34: Mike | D34: UFA | E34: JT Miller | F34: 5 | G34: 2 | U34: =if($D34=U$1,$F34,"") -> 5 | V34: =rank(U34,$U$2:$U$173) -> 16 | W34: =if($D34=W$1,$F34,"") | X34: =rank(W34,$W$2:$W$173) -> #N/A
A35: =A34+1 -> 34 | B35: Mike | C35: Lloyd | D35: RFA | E35: Brady Tkachuk | F35: 3 | G35: 5 | U35: =if($D35=U$1,$F35,"") | V35: =rank(U35,$U$2:$U$173) -> #N/A | W35: =if($D35=W$1,$F35,"") -> 3 | X35: =rank(W35,$W$2:$W$173) -> 17
A36: =A35+1 -> 35 | B36: Mike | C36: Craig | D36: UFA | E36: Darcy Kuemper | F36: 6.4 | G36: 1 | U36: =if($D36=U$1,$F36,"") -> 6.4 | V36: =rank(U36,$U$2:$U$173) -> 3 | W36: =if($D36=W$1,$F36,"") | X36: =rank(W36,$W$2:$W$173) -> #N/A
A37: =A36+1 -> 36 | B37: Searle | C37: Mike | D37: RFA | E37: Elias Pettersson | F37: 3.1 | G37: 4 | U37: =if($D37=U$1,$F37,"") | V37: =rank(U37,$U$2:$U$173) -> #N/A | W37: =if($D37=W$1,$F37,"") -> 3.1 | X37: =rank(W37,$W$2:$W$173) -> 16
A38: =A37+1 -> 37 | B38: Searle | C38: Tevie | D38: UFA | E38: Tyson Barrie | F38: 2 | G38: 1 | U38: =if($D38=U$1,$F38,"") -> 2 | V38: =rank(U38,$U$2:$U$173) -> 44 | W38: =if($D38=W$1,$F38,"") | X38: =rank(W38,$W$2:$W$173) -> #N/A
A39: =A38+1 -> 38 | B39: Masliyah | C39: Staav | D39: UFA | E39: MacKenzie Weegar | F39: 2.2 | G39: 2 | U39: =if($D39=U$1,$F39,"") -> 2.2 | V39: =rank(U39,$U$2:$U$173) -> 38 | W39: =if($D39=W$1,$F39,"") | X39: =rank(W39,$W$2:$W$173) -> #N/A
A40: =A39+1 -> 39 | B40: Zale | C40: Lloyd | D40: RFA | E40: Teuvo Teravainen | F40: 4.1 | G40: 2 | U40: =if($D40=U$1,$F40,"") | V40: =rank(U40,$U$2:$U$173) -> #N/A | W40: =if($D40=W$1,$F40,"") -> 4.1 | X40: =rank(W40,$W$2:$W$173) -> 10
...

Sheet 2021
A1: Pick | B1: Intro | C1: Winner | D1: Type | E1: Name | F1: Salary | G1: Term | H1: Picks Transferred | U1: UFA | V1: UFA Rank | W1: RFA | X1: RFA Rank
A2: 1 | B2: Shafran | C2: Shafran | D2: RFA | E2: Andrei Vasilevskiy | F2: 8.6 | G2: 3 | U2: =if($D2=U$1,$F2,"") | V2: =rank(U2,$U$2:$U$173) -> #N/A | W2: =if($D2=W$1,$F2,"") -> 8.6 | X2: =rank(W2,$W$2:$W$173) -> 1
A3: =A2+1 -> 2 | B3: Shafran | C3: Masliyah | D3: UFA | E3: Connor Hellbuyck | F3: 7.8 | G3: 2 | U3: =if($D3=U$1,$F3,"") -> 7.8 | V3: =rank(U3,$U$2:$U$173) -> 3 | W3: =if($D3=W$1,$F3,"") | X3: =rank(W3,$W$2:$W$173) -> #N/A
A4: =A3+1 -> 3 | B4: Tevie | C4: Kyle | D4: RFA | E4: Tony DeAngelo | F4: 3 | G4: 4 | H4: 2022 3rd (LSD) | U4: =if($D4=U$1,$F4,"") | V4: =rank(U4,$U$2:$U$173) -> #N/A | W4: =if($D4=W$1,$F4,"") -> 3 | X4: =rank(W4,$W$2:$W$173) -> 7
A5: =A4+1 -> 4 | B5: Tevie | C5: Mike | D5: UFA | E5: Alex Ovechkin | F5: 5.6 | G5: 1 | U5: =if($D5=U$1,$F5,"") -> 5.6 | V5: =rank(U5,$U$2:$U$173) -> 11 | W5: =if($D5=W$1,$F5,"") | X5: =rank(W5,$W$2:$W$173) -> #N/A
A6: =A5+1 -> 5 | B6: Kyle | C6: Tevie | D6: RFA | E6: Dylan Larkin | F6: 2.4 | G6: 4 | U6: =if($D6=U$1,$F6,"") | V6: =rank(U6,$U$2:$U$173) -> #N/A | W6: =if($D6=W$1,$F6,"") -> 2.4 | X6: =rank(W6,$W$2:$W$173) -> 10
A7: =A6+1 -> 6 | B7: Kyle | C7: Zale | D7: UFA | E7: Mike Smith | F7: 2.1 | G7: 1 | U7: =if($D7=U$1,$F7,"") -> 2.1 | V7: =rank(U7,$U$2:$U$173) -> 52 | W7: =if($D7=W$1,$F7,"") | X7: =rank(W7,$W$2:$W$173) -> #N/A
A8: =A7+1 -> 7 | B8: Drew | C8: Tevie | D8: UFA | E8: Petr Mrazek | F8: 1.1 | G8: 1 | U8: =if($D8=U$1,$F8,"") -> 1.1 | V8: =rank(U8,$U$2:$U$173) -> 76 | W8: =if($D8=W$1,$F8,"") | X8: =rank(W8,$W$2:$W$173) -> #N/A
A9: =A8+1 -> 8 | B9: Masliyah | C9: Masliyah | D9: RFA | E9: Gabriel Landeskog | F9: 5.2 | G9: 4 | U9: =if($D9=U$1,$F9,"") | V9: =rank(U9,$U$2:$U$173) -> #N/A | W9: =if($D9=W$1,$F9,"") -> 5.2 | X9: =rank(W9,$W$2:$W$173) -> 3
A10: =A9+1 -> 9 | B10: Masliyah | C10: Staav | D10: UFA | E10: Sidney Crosby | F10: 6.7 | G10: 1 | U10: =if($D10=U$1,$F10,"") -> 6.7 | V10: =rank(U10,$U$2:$U$173) -> 6 | W10: =if($D10=W$1,$F10,"") | X10: =rank(W10,$W$2:$W$173) -> #N/A
A11: =A10+1 -> 10 | B11: Craig | C11: Masliyah | D11: RFA | E11: Mitch Marner | F11: 6.4 | G11: 3 | U11: =if($D11=U$1,$F11,"") | V11: =rank(U11,$U$2:$U$173) -> #N/A | W11: =if($D11=W$1,$F11,"") -> 6.4 | X11: =rank(W11,$W$2:$W$173) -> 2
A12: =A11+1 -> 11 | B12: Craig | C12: Tevie | D12: UFA | E12: Jack Campbell | F12: 4 | G12: 1 | U12: =if($D12=U$1,$F12,"") -> 4 | V12: =rank(U12,$U$2:$U$173) -> 22 | W12: =if($D12=W$1,$F12,"") | X12: =rank(W12,$W$2:$W$173) -> #N/A
A13: =A12+1 -> 12 | B13: Staav | C13: Zale | D13: RFA | E13: Juuse Saros | F13: 2.4 | G13: 4 | U13: =if($D13=U$1,$F13,"") | V13: =rank(U13,$U$2:$U$173) -> #N/A | W13: =if($D13=W$1,$F13,"") -> 2.4 | X13: =rank(W13,$W$2:$W$173) -> 10
A14: =A13+1 -> 13 | B14: Staav | C14: Craig | D14: UFA | E14: David Perron | F14: 4.3 | G14: 1 | U14: =if($D14=U$1,$F14,"") -> 4.3 | V14: =rank(U14,$U$2:$U$173) -> 18 | W14: =if($D14=W$1,$F14,"") | X14: =rank(W14,$W$2:$W$173) -> #N/A
A15: =A14+1 -> 14 | B15: Zale | C15: Drew | D15: RFA | E15: Igor Shesterkin | F15: 4 | G15: 3 | U15: =if($D15=U$1,$F15,"") | V15: =rank(U15,$U$2:$U$173) -> #N/A | W15: =if($D15=W$1,$F15,"") -> 4 | X15: =rank(W15,$W$2:$W$173) -> 4
A16: =A15+1 -> 15 | B16: Zale | C16: Shafran | D16: UFA | E16: Frederik Andersen | F16: 3 | G16: 3 | U16: =if($D16=U$1,$F16,"") -> 3 | V16: =rank(U16,$U$2:$U$173) -> 33 | W16: =if($D16=W$1,$F16,"") | X16: =rank(W16,$W$2:$W$173) -> #N/A
A17: =A16+1 -> 16 | B17: Searle | C17: Lloyd | D17: RFA | E17: Darnell Nurse | F17: 3.2 | G17: 2 | H17: 2022 2nd (MAC) | U17: =if($D17=U$1,$F17,"") | V17: =rank(U17,$U$2:$U$173) -> #N/A | W17: =if($D17=W$1,$F17,"") -> 3.2 | X17: =rank(W17,$W$2:$W$173) -> 5
A18: =A17+1 -> 17 | B18: Searle | C18: Craig | D18: UFA | E18: Zach Hyman | F18: 4.7 | G18: 1 | U18: =if($D18=U$1,$F18,"") -> 4.7 | V18: =rank(U18,$U$2:$U$173) -> 15 | W18: =if($D18=W$1,$F18,"") | X18: =rank(W18,$W$2:$W$173) -> #N/A
A19: =A18+1 -> 18 | B19: Lloyd | C19: Zale | D19: RFA | E19: Thomas Chabot | F19: 3.2 | G19: 6 | U19: =if($D19=U$1,$F19,"") | V19: =rank(U19,$U$2:$U$173) -> #N/A | W19: =if($D19=W$1,$F19,"") -> 3.2 | X19: =rank(W19,$W$2:$W$173) -> 5
A20: =A19+1 -> 19 | B20: Lloyd | C20: Searle | D20: UFA | E20: Tyson Barrie | F20: 5.1 | G20: 1 | U20: =if($D20=U$1,$F20,"") -> 5.1 | V20: =rank(U20,$U$2:$U$173) -> 14 | W20: =if($D20=W$1,$F20,"") | X20: =rank(W20,$W$2:$W$173) -> #N/A
A21: =A20+1 -> 20 | B21: Mike | C21: Staav | D21: RFA | E21: Miro Heiskanen | F21: 2.8 | G21: 3 | H21: 2022 3rd (LGN) | U21: =if($D21=U$1,$F21,"") | V21: =rank(U21,$U$2:$U$173) -> #N/A | W21: =if($D21=W$1,$F21,"") -> 2.8 | X21: =rank(W21,$W$2:$W$173) -> 9
A22: =A21+1 -> 21 | B22: Mike | C22: Kyle | D22: UFA | E22: Artemi Panarin | F22: 8.8 | G22: 1 | U22: =if($D22=U$1,$F22,"") -> 8.8 | V22: =rank(U22,$U$2:$U$173) -> 1 | W22: =if($D22=W$1,$F22,"") | X22: =rank(W22,$W$2:$W$173) -> #N/A
A23: =A22+1 -> 22 | B23: Shafran | C23: Staav | D23: RFA | E23: Thatcher Demko | F23: 2.4 | G23: 2 | U23: =if($D23=U$1,$F23,"") | V23: =rank(U23,$U$2:$U$173) -> #N/A | W23: =if($D23=W$1,$F23,"") -> 2.4 | X23: =rank(W23,$W$2:$W$173) -> 10
A24: =A23+1 -> 23 | B24: Shafran | C24: Mike | D24: UFA | E24: Patrik Kane | F24: 8.4 | G24: 1 | U24: =if($D24=U$1,$F24,"") -> 8.4 | V24: =rank(U24,$U$2:$U$173) -> 2 | W24: =if($D24=W$1,$F24,"") | X24: =rank(W24,$W$2:$W$173) -> #N/A
A25: =A24+1 -> 24 | B25: Tevie | C25: Tevie | D25: RFA | E25: Alex Tuch | F25: 0.8 | G25: 3 | U25: =if($D25=U$1,$F25,"") | V25: =rank(U25,$U$2:$U$173) -> #N/A | W25: =if($D25=W$1,$F25,"") -> 0.8 | X25: =rank(W25,$W$2:$W$173) -> 22
A26: =A25+1 -> 25 | B26: Tevie | C26: Tevie | D26: UFA | E26: Marc-Andre Fleury | F26: 2.9 | G26: 1 | U26: =if($D26=U$1,$F26,"") -> 2.9 | V26: =rank(U26,$U$2:$U$173) -> 37 | W26: =if($D26=W$1,$F26,"") | X26: =rank(W26,$W$2:$W$173) -> #N/A
A27: =A26+1 -> 26 | B27: Kyle | C27: Mike | D27: RFA | E27: Zach Werenski | F27: 1.9 | G27: 3 | H27: 2022 2nd (JHN) | U27: =if($D27=U$1,$F27,"") | V27: =rank(U27,$U$2:$U$173) -> #N/A | W27: =if($D27=W$1,$F27,"") -> 1.9 | X27: =rank(W27,$W$2:$W$173) -> 14
A28: =A27+1 -> 27 | B28: Kyle | C28: Drew | D28: UFA | E28: Dougie Hamilton | F28: 4.2 | G28: 1 | U28: =if($D28=U$1,$F28,"") -> 4.2 | V28: =rank(U28,$U$2:$U$173) -> 19 | W28: =if($D28=W$1,$F28,"") | X28: =rank(W28,$W$2:$W$173) -> #N/A
A29: =A28+1 -> 28 | B29: Drew | C29: Zale | D29: RFA | E29: Sam Bennett | F29: 2 | G29: 3 | H29: 2023 2nd (ZSK) | U29: =if($D29=U$1,$F29,"") | V29: =rank(U29,$U$2:$U$173) -> #N/A | W29: =if($D29=W$1,$F29,"") -> 2 | X29: =rank(W29,$W$2:$W$173) -> 13
A30: =A29+1 -> 29 | B30: Drew | C30: Staav | D30: UFA | E30: Robin Lehner | F30: 6 | G30: 1 | U30: =if($D30=U$1,$F30,"") -> 6 | V30: =rank(U30,$U$2:$U$173) -> 9 | W30: =if($D30=W$1,$F30,"") | X30: =rank(W30,$W$2:$W$173) -> #N/A
A31: =A30+1 -> 30 | B31: Masliyah | C31: Craig | D31: UFA | E31: Johnny Gaudreau | F31: 4 | G31: 2 | U31: =if($D31=U$1,$F31,"") -> 4 | V31: =rank(U31,$U$2:$U$173) -> 22 | W31: =if($D31=W$1,$F31,"") | X31: =rank(W31,$W$2:$W$173) -> #N/A
A32: =A31+1 -> 31 | B32: Craig | C32: Zale | D32: RFA | E32: Connor Garland | F32: 1.7 | G32: 2 | U32: =if($D32=U$1,$F32,"") | V32: =rank(U32,$U$2:$U$173) -> #N/A | W32: =if($D32=W$1,$F32,"") -> 1.7 | X32: =rank(W32,$W$2:$W$173) -> 15
A33: =A32+1 -> 32 | B33: Craig | C33: Searle | D33: UFA | E33: Mark Stone | F33: 6.1 | G33: 1 | U33: =if($D33=U$1,$F33,"") -> 6.1 | V33: =rank(U33,$U$2:$U$173) -> 8 | W33: =if($D33=W$1,$F33,"") | X33: =rank(W33,$W$2:$W$173) -> #N/A
A34: =A33+1 -> 33 | B34: Staav | C34: Searle | D34: UFA | E34: Darcy Kuemper | F34: 5.6 | G34: 1 | U34: =if($D34=U$1,$F34,"") -> 5.6 | V34: =rank(U34,$U$2:$U$173) -> 11 | W34: =if($D34=W$1,$F34,"") | X34: =rank(W34,$W$2:$W$173) -> #N/A
A35: =A34+1 -> 34 | B35: Zale | C35: Shafran | D35: UFA | E35: Ryan O'reilly | F35: 4.6 | G35: 1 | U35: =if($D35=U$1,$F35,"") -> 4.6 | V35: =rank(U35,$U$2:$U$173) -> 16 | W35: =if($D35=W$1,$F35,"") | X35: =rank(W35,$W$2:$W$173) -> #N/A
A36: =A35+1 -> 35 | B36: Searle | C36: Kyle | D36: RFA | E36: Kasperin Kananen | F36: 0.9 | G36: 3 | U36: =if($D36=U$1,$F36,"") | V36: =rank(U36,$U$2:$U$173) -> #N/A | W36: =if($D36=W$1,$F36,"") -> 0.9 | X36: =rank(W36,$W$2:$W$173) -> 19
A37: =A36+1 -> 36 | B37: Searle | C37: Craig | D37: UFA | E37: Vincent Trocheck | F37: 3.2 | G37: 1 | U37: =if($D37=U$1,$F37,"") -> 3.2 | V37: =rank(U37,$U$2:$U$173) -> 31 | W37: =if($D37=W$1,$F37,"") | X37: =rank(W37,$W$2:$W$173) -> #N/A
A38: =A37+1 -> 37 | B38: Lloyd | C38: Lloyd | D38: UFA | E38: Jeff Petry | F38: 3.3 | G38: 1 | U38: =if($D38=U$1,$F38,"") -> 3.3 | V38: =rank(U38,$U$2:$U$173) -> 29 | W38: =if($D38=W$1,$F38,"") | X38: =rank(W38,$W$2:$W$173) -> #N/A
A39: =A38+1 -> 38 | B39: Mike | C39: Kyle | D39: RFA | E39: Jakub Vrana | F39: 1.5 | G39: 3 | U39: =if($D39=U$1,$F39,"") | V39: =rank(U39,$U$2:$U$173) -> #N/A | W39: =if($D39=W$1,$F39,"") -> 1.5 | X39: =rank(W39,$W$2:$W$173) -> 16
A40: =A39+1 -> 39 | B40: Mike | C40: Tevie | D40: UFA | E40: John Tavares | F40: 6.9 | G40: 1 | U40: =if($D40=U$1,$F40,"") -> 6.9 | V40: =rank(U40,$U$2:$U$173) -> 5 | W40: =if($D40=W$1,$F40,"") | X40: =rank(W40,$W$2:$W$173) -> #N/A
...

Sheet 2020
A1: Pick | B1: Intro | C1: Winner | D1: Type | E1: Name | F1: Salary | G1: Term | H1: Picks Transferred | U1: UFA | V1: UFA Rank | W1: RFA | X1: RFA Rank
A2: 1 | B2: Tevie | C2: Masliyah | D2: RFA | E2: Auston Matthews | F2: 6.5 | G2: 5 | U2: =if($D2=U$1,$F2,"") | V2: =rank(U2,$U$2:$U$173) -> #N/A | W2: =if($D2=W$1,$F2,"") -> 6.5 | X2: =rank(W2,$W$2:$W$173) -> 3
A3: =A2+1 -> 2 | B3: Tevie | C3: Kyle | D3: UFA | E3: Max Pacioretty | F3: 3.1 | G3: 1 | U3: =if($D3=U$1,$F3,"") -> 3.1 | V3: =rank(U3,$U$2:$U$173) -> 32 | W3: =if($D3=W$1,$F3,"") | X3: =rank(W3,$W$2:$W$173) -> #N/A
A4: =A3+1 -> 3 | B4: Shafran | C4: Searle | D4: RFA | E4: Brayden Point | F4: 6.8 | G4: 3 | U4: =if($D4=U$1,$F4,"") | V4: =rank(U4,$U$2:$U$173) -> #N/A | W4: =if($D4=W$1,$F4,"") -> 6.8 | X4: =rank(W4,$W$2:$W$173) -> 1
A5: =A4+1 -> 4 | B5: Shafran | C5: Tevie | D5: UFA | E5: Frederik Andersen | F5: 6.6 | G5: 1 | U5: =if($D5=U$1,$F5,"") -> 6.6 | V5: =rank(U5,$U$2:$U$173) -> 6 | W5: =if($D5=W$1,$F5,"") | X5: =rank(W5,$W$2:$W$173) -> #N/A
A6: =A5+1 -> 5 | B6: Staav | C6: Mike | D6: RFA | E6: Jack Eichel | F6: 6.6 | G6: 6 | U6: =if($D6=U$1,$F6,"") | V6: =rank(U6,$U$2:$U$173) -> #N/A | W6: =if($D6=W$1,$F6,"") -> 6.6 | X6: =rank(W6,$W$2:$W$173) -> 2
A7: =A6+1 -> 6 | B7: Staav | C7: Kyle | D7: UFA | E7: John Carlson | F7: 5.2 | G7: 1 | U7: =if($D7=U$1,$F7,"") -> 5.2 | V7: =rank(U7,$U$2:$U$173) -> 13 | W7: =if($D7=W$1,$F7,"") | X7: =rank(W7,$W$2:$W$173) -> #N/A
A8: =A7+1 -> 7 | B8: Zale | C8: Staav | D8: RFA | E8: Sebastian Aho | F8: 5.6 | G8: 3 | U8: =if($D8=U$1,$F8,"") | V8: =rank(U8,$U$2:$U$173) -> #N/A | W8: =if($D8=W$1,$F8,"") -> 5.6 | X8: =rank(W8,$W$2:$W$173) -> 6
A9: =A8+1 -> 8 | B9: Zale | C9: Staav | D9: UFA | E9: Artemi Panarin | F9: 9 | G9: 1 | U9: =if($D9=U$1,$F9,"") -> 9 | V9: =rank(U9,$U$2:$U$173) -> 1 | W9: =if($D9=W$1,$F9,"") | X9: =rank(W9,$W$2:$W$173) -> #N/A
A10: =A9+1 -> 9 | B10: Mike | C10: Tevie | D10: RFA | E10: Aleksander Barkov | F10: 5.4 | G10: 4 | U10: =if($D10=U$1,$F10,"") | V10: =rank(U10,$U$2:$U$173) -> #N/A | W10: =if($D10=W$1,$F10,"") -> 5.4 | X10: =rank(W10,$W$2:$W$173) -> 7
A11: =A10+1 -> 10 | B11: Mike | C11: Shafran | D11: UFA | E11: Steven Stamkos | F11: 8.6 | G11: 1 | U11: =if($D11=U$1,$F11,"") -> 8.6 | V11: =rank(U11,$U$2:$U$173) -> 2 | W11: =if($D11=W$1,$F11,"") | X11: =rank(W11,$W$2:$W$173) -> #N/A
A12: =A11+1 -> 11 | B12: Searle | C12: Lloyd | D12: RFA | E12: Matthew Tkachuk | F12: 4.8 | G12: 2 | U12: =if($D12=U$1,$F12,"") | V12: =rank(U12,$U$2:$U$173) -> #N/A | W12: =if($D12=W$1,$F12,"") -> 4.8 | X12: =rank(W12,$W$2:$W$173) -> 9
A13: =A12+1 -> 12 | B13: Searle | C13: Drew | D13: UFA | E13: Tyson Barrie | F13: 4 | G13: 1 | U13: =if($D13=U$1,$F13,"") -> 4 | V13: =rank(U13,$U$2:$U$173) -> 23 | W13: =if($D13=W$1,$F13,"") | X13: =rank(W13,$W$2:$W$173) -> #N/A
A14: =A13+1 -> 13 | B14: Masliyah | C14: Craig | D14: RFA | E14: Sean Couturier | F14: 3.3 | G14: 3 | U14: =if($D14=U$1,$F14,"") | V14: =rank(U14,$U$2:$U$173) -> #N/A | W14: =if($D14=W$1,$F14,"") -> 3.3 | X14: =rank(W14,$W$2:$W$173) -> 13
... A156: =A155+1 -> 155 | B156: Mike | C156: Mike | D156: UFA | E156: Collin Delia | F156: 0.5 | G156: 2 | U156: =if($D156=U$1,$F156,"") -> 0.5 | V156: =rank(U156,$U$2:$U$173) -> 101 | W156: =if($D156=W$1,$F156,"") | X156: =rank(W156,$W$2:$W$173) -> #N/A
U157: =if($D157=U$1,$F157,"") | W157: =if($D157=W$1,$F157,"")
U158: =if($D158=U$1,$F158,"") | W158: =if($D158=W$1,$F158,"")
U159: =if($D159=U$1,$F159,"") | W159: =if($D159=W$1,$F159,"")
U160: =if($D160=U$1,$F160,"") | W160: =if($D160=W$1,$F160,"")
U161: =if($D161=U$1,$F161,"") | W161: =if($D161=W$1,$F161,"")
U162: =if($D162=U$1,$F162,"") | W162: =if($D162=W$1,$F162,"")
U163: =if($D163=U$1,$F163,"") | W163: =if($D163=W$1,$F163,"")
U164: =if($D164=U$1,$F164,"") | W164: =if($D164=W$1,$F164,"")
U165: =if($D165=U$1,$F165,"") | W165: =if($D165=W$1,$F165,"")
U166: =if($D166=U$1,$F166,"") | W166: =if($D166=W$1,$F166,"")
U167: =if($D167=U$1,$F167,"") | W167: =if($D167=W$1,$F167,"")
U168: =if($D168=U$1,$F168,"") | W168: =if($D168=W$1,$F168,"")
... U173: =if($D173=U$1,$F173,"") | W173: =if($D173=W$1,$F173,"")

Sheet 2019
A1: Pick | B1: Intro | C1: Winner | D1: Type | E1: Name | F1: Salary | G1: Term | H1: Picks Transferred | U1: UFA | V1: UFA Rank | W1: RFA | X1: RFA Rank
A2: 1 | B2: Tevie | C2: Shafran | D2: RFA | E2: Andrei Vasilevski | F2: 8.6 | G2: 2 | U2: =if($D2=U$1,$F2,"") | V2: =rank(U2,$U$2:$U$173) -> #N/A | W2: =if($D2=W$1,$F2,"") -> 8.6 | X2: =rank(W2,$W$2:$W$173) -> 1
A3: =A2+1 -> 2 | B3: Tevie | C3: Tevie | D3: UFA | E3: Nicklas Backstrom | F3: 4.6 | G3: 1 | U3: =if($D3=U$1,$F3,"") -> 4.6 | V3: =rank(U3,$U$2:$U$173) -> 17 | W3: =if($D3=W$1,$F3,"") | X3: =rank(W3,$W$2:$W$173) -> #N/A
A4: =A3+1 -> 3 | B4: Zale | C4: Tevie | D4: RFA | E4: Nathan MacKinnon | F4: 8.1 | G4: 4 | U4: =if($D4=U$1,$F4,"") | V4: =rank(U4,$U$2:$U$173) -> #N/A | W4: =if($D4=W$1,$F4,"") -> 8.1 | X4: =rank(W4,$W$2:$W$173) -> 2
A5: =A4+1 -> 4 | B5: Zale | C5: Staav | D5: UFA | E5: Steven Stamkos | F5: 9 | G5: 1 | U5: =if($D5=U$1,$F5,"") -> 9 | V5: =rank(U5,$U$2:$U$173) -> 1 | W5: =if($D5=W$1,$F5,"") | X5: =rank(W5,$W$2:$W$173) -> #N/A
A6: =A5+1 -> 5 | B6: Searle | C6: Zale | D6: RFA | E6: David Pastrnak | F6: 6.2 | G6: 4 | U6: =if($D6=U$1,$F6,"") | V6: =rank(U6,$U$2:$U$173) -> #N/A | W6: =if($D6=W$1,$F6,"") -> 6.2 | X6: =rank(W6,$W$2:$W$173) -> 4
A7: =A6+1 -> 6 | B7: Searle | C7: Kyle | D7: UFA | E7: Anze Kopitar | F7: 2.9 | G7: 1 | U7: =if($D7=U$1,$F7,"") -> 2.9 | V7: =rank(U7,$U$2:$U$173) -> 31 | W7: =if($D7=W$1,$F7,"") | X7: =rank(W7,$W$2:$W$173) -> #N/A
A8: =A7+1 -> 7 | B8: Shafran | C8: Tevie | D8: RFA | E8: Matt Murray | F8: 4.1 | G8: 3 | U8: =if($D8=U$1,$F8,"") | V8: =rank(U8,$U$2:$U$173) -> #N/A | W8: =if($D8=W$1,$F8,"") -> 4.1 | X8: =rank(W8,$W$2:$W$173) -> 8
A9: =A8+1 -> 8 | B9: Shafran | C9: Drew | D9: UFA | E9: Sergei Bobrovsky | F9: 7.5 | G9: 1 | U9: =if($D9=U$1,$F9,"") -> 7.5 | V9: =rank(U9,$U$2:$U$173) -> 6 | W9: =if($D9=W$1,$F9,"") | X9: =rank(W9,$W$2:$W$173) -> #N/A
A10: =A9+1 -> 9 | B10: Staav | C10: Mike | D10: RFA | E10: Sean Monahan | F10: 5 | G10: 3 | U10: =if($D10=U$1,$F10,"") | V10: =rank(U10,$U$2:$U$173) -> #N/A | W10: =if($D10=W$1,$F10,"") -> 5 | X10: =rank(W10,$W$2:$W$173) -> 6
A11: =A10+1 -> 10 | B11: Staav | C11: Kyle | D11: UFA | E11: Phil Kessel | F11: 4.3 | G11: 1 | U11: =if($D11=U$1,$F11,"") -> 4.3 | V11: =rank(U11,$U$2:$U$173) -> 19 | W11: =if($D11=W$1,$F11,"") | X11: =rank(W11,$W$2:$W$173) -> #N/A
A12: =A11+1 -> 11 | B12: Masliyah | C12: Lloyd | D12: RFA | E12: Tomas Hertl | F12: 4.5 | G12: 3 | U12: =if($D12=U$1,$F12,"") | V12: =rank(U12,$U$2:$U$173) -> #N/A | W12: =if($D12=W$1,$F12,"") -> 4.5 | X12: =rank(W12,$W$2:$W$173) -> 7
A13: =A12+1 -> 12 | B13: Masliyah | C13: Craig | D13: UFA | E13: Kris Letang | F13: 3.6 | G13: 1 | U13: =if($D13=U$1,$F13,"") -> 3.6 | V13: =rank(U13,$U$2:$U$173) -> 23 | W13: =if($D13=W$1,$F13,"") | X13: =rank(W13,$W$2:$W$173) -> #N/A
A14: =A13+1 -> 13 | B14: Mike | C14: Lloyd | D14: RFA | E14: Teuvo Teravainen | F14: 4.1 | G14: 3 | U14: =if($D14=U$1,$F14,"") | V14: =rank(U14,$U$2:$U$173) -> #N/A | W14: =if($D14=W$1,$F14,"") -> 4.1 | X14: =rank(W14,$W$2:$W$173) -> 8
... A135: =A134+1 -> 134 | B135: Tevie | C135: Tevie | D135: UFA | E135: Craig Anderson | F135: 0.5 | G135: 1 | U135: =if($D135=U$1,$F135,"") -> 0.5 | V135: =rank(U135,$U$2:$U$173) -> 99 | W135: =if($D135=W$1,$F135,"") | X135: =rank(W135,$W$2:$W$173) -> #N/A
U136: =if($D136=U$1,$F136,"") | W136: =if($D136=W$1,$F136,"")
U137: =if($D137=U$1,$F137,"") | W137: =if($D137=W$1,$F137,"")
U138: =if($D138=U$1,$F138,"") | W138: =if($D138=W$1,$F138,"")
U139: =if($D139=U$1,$F139,"") | W139: =if($D139=W$1,$F139,"")
U140: =if($D140=U$1,$F140,"") | W140: =if($D140=W$1,$F140,"")
U141: =if($D141=U$1,$F141,"") | W141: =if($D141=W$1,$F141,"")
U142: =if($D142=U$1,$F142,"") | W142: =if($D142=W$1,$F142,"")
U143: =if($D143=U$1,$F143,"") | W143: =if($D143=W$1,$F143,"")
U144: =if($D144=U$1,$F144,"") | W144: =if($D144=W$1,$F144,"")
U145: =if($D145=U$1,$F145,"") | W145: =if($D145=W$1,$F145,"")
U146: =if($D146=U$1,$F146,"") | W146: =if($D146=W$1,$F146,"")
U147: =if($D147=U$1,$F147,"") | W147: =if($D147=W$1,$F147,"")
... U173: =if($D173=U$1,$F173,"") | W173: =if($D173=W$1,$F173,"")

Sheet 2018
A1: Pick | B1: Intro | C1: Winner | D1: Type | E1: Name | F1: Salary | G1: Term | H1: Picks Transferred | U1: UFA | V1: UFA Rank | W1: RFA | X1: RFA Rank
A2: 1 | B2: Craig | C2: Drew | D2: RFA | E2: Connor McDavid | F2: 11.4 | G2: 6 | U2: =if($D2=U$1,$F2,"") | V2: =rank(U2,$U$2:$U$173) -> #N/A | W2: =if($D2=W$1,$F2,"") -> 11.4 | X2: =rank(W2,$W$2:$W$173) -> 1
A3: =A2+1 -> 2 | B3: Craig | C3: Tevie | D3: UFA | E3: Sidney Crosby | F3: 10 | G3: 1 | U3: =if($D3=U$1,$F3,"") -> 10 | V3: =rank(U3,$U$2:$U$173) -> 1 | W3: =if($D3=W$1,$F3,"") | X3: =rank(W3,$W$2:$W$173) -> #N/A
A4: =A3+1 -> 3 | B4: Searle | C4: Masliyah | D4: RFA | E4: Connor Hellebuyck | F4: 8.8 | G4: 3 | U4: =if($D4=U$1,$F4,"") | V4: =rank(U4,$U$2:$U$173) -> #N/A | W4: =if($D4=W$1,$F4,"") -> 8.8 | X4: =rank(W4,$W$2:$W$173) -> 3
A5: =A4+1 -> 4 | B5: Searle | C5: Craig | D5: UFA | E5: Alex Ovechkin | F5: 7.6 | G5: 1 | U5: =if($D5=U$1,$F5,"") -> 7.6 | V5: =rank(U5,$U$2:$U$173) -> 8 | W5: =if($D5=W$1,$F5,"") | X5: =rank(W5,$W$2:$W$173) -> #N/A
A6: =A5+1 -> 5 | B6: Shafran | C6: Searle | D6: RFA | E6: Nikita Kucherov | F6: 9.2 | G6: 4 | U6: =if($D6=U$1,$F6,"") | V6: =rank(U6,$U$2:$U$173) -> #N/A | W6: =if($D6=W$1,$F6,"") -> 9.2 | X6: =rank(W6,$W$2:$W$173) -> 2
A7: =A6+1 -> 6 | B7: Shafran | C7: Shafran | D7: UFA | E7: Pekka Rinne | F7: 8.7 | G7: 1 | U7: =if($D7=U$1,$F7,"") -> 8.7 | V7: =rank(U7,$U$2:$U$173) -> 5 | W7: =if($D7=W$1,$F7,"") | X7: =rank(W7,$W$2:$W$173) -> #N/A
A8: =A7+1 -> 7 | B8: Tevie | C8: Lloyd | D8: RFA | E8: Filip Forsberg | F8: 6.3 | G8: 3 | U8: =if($D8=U$1,$F8,"") | V8: =rank(U8,$U$2:$U$173) -> #N/A | W8: =if($D8=W$1,$F8,"") -> 6.3 | X8: =rank(W8,$W$2:$W$173) -> 6
A9: =A8+1 -> 8 | B9: Tevie | C9: Staav | D9: UFA | E9: John Tavares | F9: 9.4 | G9: 1 | U9: =if($D9=U$1,$F9,"") -> 9.4 | V9: =rank(U9,$U$2:$U$173) -> 2 | W9: =if($D9=W$1,$F9,"") | X9: =rank(W9,$W$2:$W$173) -> #N/A
A10: =A9+1 -> 9 | B10: Staav | C10: Craig | D10: RFA | E10: Taylor Hall | F10: 7.4 | G10: 3 | U10: =if($D10=U$1,$F10,"") | V10: =rank(U10,$U$2:$U$173) -> #N/A | W10: =if($D10=W$1,$F10,"") -> 7.4 | X10: =rank(W10,$W$2:$W$173) -> 4
A11: =A10+1 -> 10 | B11: Staav | C11: Mike | D11: UFA | E11: Evgeni Malkin | F11: 8.9 | G11: 1 | U11: =if($D11=U$1,$F11,"") -> 8.9 | V11: =rank(U11,$U$2:$U$173) -> 4 | W11: =if($D11=W$1,$F11,"") | X11: =rank(W11,$W$2:$W$173) -> #N/A
A12: =A11+1 -> 11 | B12: Mike | C12: Shafran | D12: RFA | E12: Leon Draisaitl | F12: 5.2 | G12: 5 | U12: =if($D12=U$1,$F12,"") | V12: =rank(U12,$U$2:$U$173) -> #N/A | W12: =if($D12=W$1,$F12,"") -> 5.2 | X12: =rank(W12,$W$2:$W$173) -> 7
A13: =A12+1 -> 12 | B13: Mike | C13: Craig | D13: UFA | E13: William Karlsson | F13: 4.6 | G13: 3 | U13: =if($D13=U$1,$F13,"") -> 4.6 | V13: =rank(U13,$U$2:$U$173) -> 25 | W13: =if($D13=W$1,$F13,"") | X13: =rank(W13,$W$2:$W$173) -> #N/A
A14: =A13+1 -> 13 | B14: Drew | C14: Lloyd | D14: UFA | E14: Braden Holtby | F14: 8.3 | G14: 1 | U14: =if($D14=U$1,$F14,"") -> 8.3 | V14: =rank(U14,$U$2:$U$173) -> 6 | W14: =if($D14=W$1,$F14,"") | X14: =rank(W14,$W$2:$W$173) -> #N/A
... A155: =A154+1 -> 154 | B155: Staav | C155: Staav | D155: UFA | E155: Olli Maata | F155: 0.5 | G155: 1 | U155: =if($D155=U$1,$F155,"") -> 0.5 | V155: =rank(U155,$U$2:$U$173) -> 111 | W155: =if($D155=W$1,$F155,"") | X155: =rank(W155,$W$2:$W$173) -> #N/A
U156: =if($D156=U$1,$F156,"") | W156: =if($D156=W$1,$F156,"")
U157: =if($D157=U$1,$F157,"") | W157: =if($D157=W$1,$F157,"")
U158: =if($D158=U$1,$F158,"") | W158: =if($D158=W$1,$F158,"")
U159: =if($D159=U$1,$F159,"") | W159: =if($D159=W$1,$F159,"")
U160: =if($D160=U$1,$F160,"") | W160: =if($D160=W$1,$F160,"")
U161: =if($D161=U$1,$F161,"") | W161: =if($D161=W$1,$F161,"")
U162: =if($D162=U$1,$F162,"") | W162: =if($D162=W$1,$F162,"")
U163: =if($D163=U$1,$F163,"") | W163: =if($D163=W$1,$F163,"")
U164: =if($D164=U$1,$F164,"") | W164: =if($D164=W$1,$F164,"")
U165: =if($D165=U$1,$F165,"") | W165: =if($D165=W$1,$F165,"")
U166: =if($D166=U$1,$F166,"") | W166: =if($D166=W$1,$F166,"")
U167: =if($D167=U$1,$F167,"") | W167: =if($D167=W$1,$F167,"")
... U173: =if($D173=U$1,$F173,"") | W173: =if($D173=W$1,$F173,"")

Sheet Summary
B1: 2018 | C1: 2019 | D1: 2020 | E1: 2021 | F1: 2022 | G1: 2023 | H1: 2024 | I1: 2025
A2: Drafted Players
A3: UFA | B3: =countif('2018'!$D:$D,$A3) -> 132 | C3: =countif('2019'!$D:$D,$A3) -> 113 | D3: =countif('2020'!$D:$D,$A3) -> 120 | E3: =countif('2021'!$D:$D,$A3) -> 127 | F3: =countif('2022'!$D:$D,$A3) -> 139 | G3: =countif('2023'!$D:$D,$A3) -> 138 | H3: =countif('2024'!$D:$D,$A3) -> 135 | I3: =countif('2025'!$D:$D,$A3) -> 119
A4: RFA | B4: =countif('2018'!$D:$D,$A4) -> 22 | C4: =countif('2019'!$D:$D,$A4) -> 21 | D4: =countif('2020'!$D:$D,$A4) -> 35 | E4: =countif('2021'!$D:$D,$A4) -> 24 | F4: =countif('2022'!$D:$D,$A4) -> 33 | G4: =countif('2023'!$D:$D,$A4) -> 26 | H4: =countif('2024'!$D:$D,$A4) -> 21 | I4: =countif('2025'!$D:$D,$A4) -> 20
A5: Total | B5: =counta('2018'!$D:$D)-1 -> 154 | C5: =counta('2019'!$D:$D)-1 -> 134 | D5: =counta('2020'!$D:$D)-1 -> 155 | E5: =counta('2021'!$D:$D)-1 -> 151 | F5: =counta('2022'!$D:$D)-1 -> 172 | G5: =counta('2023'!$D:$D)-1 -> 164 | H5: =counta('2024'!$D:$D)-1 -> 156 | I5: =counta('2025'!$D:$D)-1 -> 139
A6: Check | B6: =sum(B3:B4)-B5 -> 0 | C6: =sum(C3:C4)-C5 -> 0 | D6: =sum(D3:D4)-D5 -> 0 | E6: =sum(E3:E4)-E5 -> 0 | F6: =sum(F3:F4)-F5 -> 0 | G6: =sum(G3:G4)-G5 -> 0 | H6: =sum(H3:H4)-H5 -> 0 | I6: =sum(I3:I4)-I5 -> 0
A8: Average Salary
A9: UFA | B9: =averageif('2018'!$D:$D,$A9,'2018'!$F:$F) -> 2.3742424 | C9: =averageif('2019'!$D:$D,$A9,'2019'!$F:$F) -> 2.3070796 | D9: =averageif('2020'!$D:$D,$A9,'2020'!$F:$F) -> 2.1233333 | E9: =averageif('2021'!$D:$D,$A9,'2021'!$F:$F) -> 2.2346457 | F9: =averageif('2022'!$D:$D,$A9,'2022'!$F:$F) -> 1.9568345 | G9: =averageif('2023'!$D:$D,$A9,'2023'!$F:$F) -> 1.8956522 | H9: =averageif('2024'!$D:$D,$A9,'2024'!$F:$F) -> 1.8503704 | I9: =averageif('2025'!$D:$D,$A9,'2025'!$F:$F) -> 2.0630252
